Workbook

Sheet 版权申明
A1: 商标声明
A8: 注意
A9: 您购买的产品、服务或特性等应受算能公司商业合同和条款的约束，本文档中描述的全部或部分产品、服务或特性可能不在您的购买或使用范围之内。除非合同另有约定，算能公司对本文档内容不做任何明示或默示的声明或保证。
A10: 由于产品版本升级或其他原因，本文档内容会不定期进行更新。除非另有约定，本文档仅作为使用指导，本文档中的所有陈述、信息和建议不构成任何明示或暗示的担保。
A13: 版权所有 © 北京算能科技有限公司 2023。保留一切权利。

Sheet 资料修订
A1: Revision Record 修订记录
A2: Date | B2: Revision Version | C2: Change Description | D2: Author
A3: 45281 | B3: V1.0 | C3: 初步版本 | D3: kaile.zhai
A4: 45467 | B4: V1.1 | C4: 1、说明页增加IO电气参数。 2、增加管脚默认状态页 | D4: miller.zhang
A5: 45491 | B5: V1.2 | C5: 1、增加PinCtrl Reg，并补充寄存器信息； 2、删除Voltage信息，补充IO Type，IO Group,PAD Name信息； | D5: qiumei.wu
A6: 45617 | B6: V1.3 | C6: 1、更正部分group信息； 2、IIC描述统一更新； | D6: qiumei.wu
A7: 45700 | B7: V1.4 | C7: 1、更正CAN0_TX默认状态； 2、补充sheet 6.MIPI_PAD切GPIO说明； | D7: qiumei.wu

Sheet 0.说明
A1: PINOUT各子表格功能说明：
A2: 1. 管脚信息表中描述芯片管脚编号，功能说明，以及对应管脚的配置寄存器等信息。 2. 功能信号表中描述功能信号，以及功能复用对应的芯片管脚。 3. 管脚控制寄存器描述管脚对应的寄存器地址，功能复用关系配置，驱动能力配置，以及上下拉电阻等配置。 4. 管脚默认状态描述芯片上电期间和上电后复位撤销后的管脚默认状态。
A3: 管脚类型说明
A5: CI | B5: Crystal Oscillator Input
A6: CO | B6: Crystal Oscillator Drive Output
A7: I | B7: Input
A8: O | B8: Output
A9: IO | B9: Input/Output
A10: B | B10: Bidirection signal
A11: A | B11: Analog setting or filtering
A12: AI | B12: Analog Input
A13: AO | B13: Analog Output
A14: AIO | B14: Analog Input/Output
A15: PI | B15: Power Supply
A16: PO | B16: Power Output
... A27: G | B27: 地。
A29: 芯片中主要有三种 IO 管脚. 管脚的电气参数如下 1. 1.8V IO 2. 18OD33 IO (1.8V mode & 3.0V mode) 3. RGMII IO (1.8V mode & 3.0V mode)
A30: 1. 1.8V IO
A31: Parameter | C31: Min | D31: Typ | E31: Max | F31: Unit
A32: VIL | B32: Input Low voltage | C32: -0.3 | E32: 0.35*VDDIO | F32: V
A33: VIH | B33: Input High voltage | C33: 0.65*VDDIO | E33: VDDIO+0.3 | F33: V
A34: VT (no pull) | B34: Threshold voltage when ST[1:0] = 00 | C34: 0.83 | D34: 0.92 | E34: 1.01 | F34: V
A35: VT_PU | B35: (no schmit trigger) | C35: 0.82 | D35: 0.91 | E35: 1
A36: VT_PD | C36: 0.84 | D36: 0.93 | E36: 1.02
A37: VT+ | B37: Threshold voltage when ST[1:0] = 01 | C37: 0.99 | D37: 1.1 | E37: 1.21 | F37: V
A38: VT- | C38: 0.74 | D38: 0.82 | E38: 0.9
A39: VT+_PU | C39: 0.98 | D39: 1.09 | E39: 1.2
A40: VT-_PU | C40: 0.73 | D40: 0.81 | E40: 0.89
A41: VT+_PD | C41: 1 | D41: 1.11 | E41: 1.22
A42: VT-_PD | C42: 0.75 | D42: 0.83 | E42: 0.91
A43: VT | B43: Threshold voltage when ST[1:0] = 1X | C43: 0.78 | D43: 0.86 | E43: 0.94 | F43: V
A44: VT+_PU | C44: 0.95 | D44: 1.05 | E44: 1.15
A45: VT-_PU | C45: 0.68 | D45: 0.76 | E45: 0.83
A46: Il | B46: Input leakage (VI = 1.8V or 0V) | E46: +/-10u | F46: A
A47: IOZ | B47: Tri-state output leakage current (VO=1.8V or 0V) | E47: +/-10u | F47: A
A48: RSPU | B48: Strong Pull up resistor | C48: 2.8K | D48: 3.5K | E48: 4.5K | F48: Ω
A49: RPU | B49: Pull up resistor | C49: 18K | D49: 25K | E49: 38K | F49: Ω
A50: RPD | B50: Pull down resistor | C50: 17K | D50: 22K | E50: 33K | F50: Ω
A51: VOL | B51: Output low voltage | E51: 0.45 | F51: V
A52: VOH | B52: Output high voltage | C52: VDDIO-0.45 | F52: V
...

Sheet 1.管脚信息表
A1: Pin Number | B1: PAD Name | C1: Pin Function | D1: IO Type | E1: IO group | F1: PinCtrl Reg | G1: IO Config Register Name | J1: Function Description
H2: Function Number | I2: Signal Name | J2: Direction | K2: Description
A3: A1 | B3: VSSC113 | C3: VSSC113 | D3: - | E3: - | F3: - | G3: - | H3: 0 | I3: VSS | J3: - | K3: 数字地。
A4: A2 | B4: AUX0 | C4: AUX0 / I2S1_MCLK / GPIO7 | D4: 1.8V GPIO | E4: 9 | F4: 0x28104930 | G4: REG_AUX0 | H4: 0 | I4: AUX | J4: O | K4: 辅助音频输出信号
G5: #N/A | H5: 1 | I5: I2S1_MCLK | J5: O | K5: I2S1或PCM1接口主时钟，可以作为音频CODEC的工作时钟
D6: G | G6: #N/A | H6: 3 | I6: GPIO7 | J6: IO | K6: 通用输入输出
A7: A3 | B7: VSSC114 | C7: VSSC114 | D7: - | E7: - | F7: - | G7: - | H7: 0 | I7: VSS | J7: - | K7: 数字地
A8: A4 | B8: XTAL_XOUT | C8: XTAL_XOUT | D8: XTAL | E8: 7 | F8: - | G8: - | H8: 0 | I8: XTAL_XOUT | J8: O | K8: RTC晶体驱动输出
A9: A5 | B9: VSSC115 | C9: VSSC115 | D9: - | E9: - | F9: - | G9: - | H9: 0 | I9: VSS | J9: - | K9: 数字地
A10: A6 | B10: PAD_MIPI0_TX4P | C10: MIPI_DSI0_P4 / VO0_D22 / GPIO182 / CAM_HS1 / IIC9_SDA / VO1_D22 | D10: 1.8V GPIO | E10: phy | F10: 0x28104EB0 | G10: REG_PAD_MIPI0_TX4P | H10: 0 | I10: MIPI_DSI0_P4 | J10: O | K10: MIPI-DSI0差分数据通道4正极
G11: #N/A | H11: 1 | I11: VO0_D22 | J11: O | K11: VO端口0数据输出22
G12: #N/A | H12: 3 | I12: GPIO182 | J12: IO | K12: 通用输入输出
G13: #N/A | H13: 5 | I13: CAM_HS1 | J13: O | K13: CAM行同步输出1
G14: #N/A | H14: 6 | I14: IIC9_SDA | J14: B | K14: IIC9总线数据/地址，OD输出。
G15: #N/A | H15: 7 | I15: VO1_D22 | J15: O | K15: VO端口1数据输出22
A16: A7 | B16: PAD_MIPI0_TX3P | C16: MIPI_DSI0_P3 / VO0_D20 / GPIO180 / CAM_HS0 / IIC8_SDA / VO1_D20 | D16: 1.8V GPIO | E16: phy | F16: 0x28104EA8 | G16: REG_PAD_MIPI0_TX3P | H16: 0 | I16: MIPI_DSI0_P3 | J16: O | K16: MIPI-DSI0差分数据通道3正极
G17: #N/A | H17: 1 | I17: VO0_D20 | J17: O | K17: VO端口0数据输出20
G18: #N/A | H18: 3 | I18: GPIO180 | J18: IO | K18: 通用输入输出
G19: #N/A | H19: 5 | I19: CAM_HS0 | J19: O | K19: CAM行同步输出0
G20: #N/A | H20: 6 | I20: IIC8_SDA | J20: B | K20: IIC8总线数据/地址，OD输出。
G21: #N/A | H21: 7 | I21: VO1_D20 | J21: O | K21: VO端口1数据输出20
A22: A8 | B22: PAD_MIPI0_TX2P | C22: MIPI_DSI0_P2 / VO0_D18 / CAM_MCLK4 / GPIO178 / CAM_HS2 / IIC7_SDA / VO1_D18 | D22: 1.8V GPIO | E22: phy | F22: 0x28104EA0 | G22: REG_PAD_MIPI0_TX2P | H22: 0 | I22: MIPI_DSI0_P2 | J22: O | K22: MIPI-DSI0差分数据通道2正极
G23: #N/A | H23: 1 | I23: VO0_D18 | J23: O | K23: VO端口0数据输出18
G24: #N/A | H24: 2 | I24: CAM_MCLK4 | J24: O | K24: 可以提供给Cam Sensor的工作时钟
G25: #N/A | H25: 3 | I25: GPIO178 | J25: IO | K25: 通用输入输出
G26: #N/A | H26: 5 | I26: CAM_HS2 | J26: O | K26: CAM行同步输出2
G27: #N/A | H27: 6 | I27: IIC7_SDA | J27: B | K27: IIC7总线数据/地址，OD输出。
G28: #N/A | H28: 7 | I28: VO1_D18 | J28: O | K28: VO端口1数据输出18
A29: A9 | B29: PAD_MIPI0_TX1P | C29: MIPI_DSI0_P1 / VO0_D16 / CAM_MCLK2 / GPIO176 / IIC6_SDA / VO1_D16 | D29: 1.8V GPIO | E29: phy | F29: 0x28104E98 | G29: REG_PAD_MIPI0_TX1P | H29: 0 | I29: MIPI_DSI0_P1 | J29: O | K29: MIPI-DSI0差分数据通道1正极
G30: #N/A | H30: 1 | I30: VO0_D16 | J30: O | K30: VO端口0数据输出16
G31: #N/A | H31: 2 | I31: CAM_MCLK2 | J31: O | K31: 可以提供给Cam Sensor的工作时钟
G32: #N/A | H32: 3 | I32: GPIO176 | J32: IO | K32: 通用输入输出
G33: #N/A | H33: 6 | I33: IIC6_SDA | J33: B | K33: IIC6总线数据/地址，OD输出。
G34: #N/A | H34: 7 | I34: VO1_D16 | J34: O | K34: VO端口1数据输出16
A35: A10 | B35: PAD_MIPI0_TX0P | C35: MIPI_DSI0_P0 / VO0_D14 / CAM_MCLK0 / GPIO174 / IIC5_SDA / VO1_D14 | D35: 1.8V GPIO | E35: phy | F35: 0x28104E90 | G35: REG_PAD_MIPI0_TX0P | H35: 0 | I35: MIPI_DSI0_P0 | J35: O | K35: MIPI-DSI0差分数据通道0正极
G36: #N/A | H36: 1 | I36: VO0_D14 | J36: O | K36: VO端口0数据输出14
G37: #N/A | H37: 2 | I37: CAM_MCLK0 | J37: O | K37: 可以提供给Cam Sensor的工作时钟
G38: #N/A | H38: 3 | I38: GPIO174 | J38: IO | K38: 通用输入输出
G39: #N/A | H39: 6 | I39: IIC5_SDA | J39: B | K39: IIC5总线数据/地址，OD输出。
G40: #N/A | H40: 7 | I40: VO1_D14 | J40: O | K40: VO端口1数据输出14
...

Sheet 2.功能信号表
A1: Interface | B1: Signal Name | C1: Description | D1: Direction | E1: Pin Name | F1: Function Number | G1: IO Config Register
A2: SPI0 | B2: SPI0_SCK | C2: {=VLOOKUP($B2&$F2,IF({1,0},'1.管脚信息表'!$I:$I&'1.管脚信息表'!$H:$H,'1.管脚信息表'!$K:$K),2,0)} -> SPI0时钟信号输出 | D2: {=VLOOKUP($B2&$F2,IF({1,0},'1.管脚信息表'!$I:$I&'1.管脚信息表'!$H:$H,'1.管脚信息表'!$J:$J),2,0)} -> O | E2: {=VLOOKUP($B2&$F2,IF({1,0},'1.管脚信息表'!$I:$I&'1.管脚信息表'!$H:$H,'1.管脚信息表'!$C:$C),2,0)} -> SPI0_SCK / I2S1_SCLK / WG0_D1 / GPIO110 / UART7_RX / PWM7 / IIC9_SCL / CAM_VS1 | F2: 0 | G2: {=VLOOKUP($B2&$F2,IF({1,0},'1.管脚信息表'!$I:$I&'1.管脚信息表'!$H:$H,'1.管脚信息表'!$G:$G),2,0)} -> REG_SPI0_SCK | H2: =AND(MATCH(B2,'1.管脚信息表'!I:I,0),MATCH(0,'1.管脚信息表'!H:H,0)) -> TRUE | J2: =IF(VLOOKUP(E2,IF({0,1},'1.管脚信息表'!$H$3:$H$2293,'1.管脚信息表'!$I$3:$I$2293),2,0)=0,"fail",VLOOKUP(E2,IF({0,1},'1.管脚信息表'!$G$3:$G$2293,'1.管脚信息表'!$I$3:$I$2293),2,0)) -> #N/A
B3: SPI0_SDO | C3: {=VLOOKUP($B3&$F3,IF({1,0},'1.管脚信息表'!$I:$I&'1.管脚信息表'!$H:$H,'1.管脚信息表'!$K:$K),2,0)} -> SPI0数据输出 | D3: {=VLOOKUP($B3&$F3,IF({1,0},'1.管脚信息表'!$I:$I&'1.管脚信息表'!$H:$H,'1.管脚信息表'!$J:$J),2,0)} -> O | E3: {=VLOOKUP($B3&$F3,IF({1,0},'1.管脚信息表'!$I:$I&'1.管脚信息表'!$H:$H,'1.管脚信息表'!$C:$C),2,0)} -> SPI0_SDO / I2S1_SDO / WG0_D0 / GPIO109 / UART7_TX / PWM6 / IIC9_SDA / CAM_HS1 | F3: 0 | G3: {=VLOOKUP($B3&$F3,IF({1,0},'1.管脚信息表'!$I:$I&'1.管脚信息表'!$H:$H,'1.管脚信息表'!$G:$G),2,0)} -> REG_SPI0_SDO
B4: SPI0_SDI | C4: {=VLOOKUP($B4&$F4,IF({1,0},'1.管脚信息表'!$I:$I&'1.管脚信息表'!$H:$H,'1.管脚信息表'!$K:$K),2,0)} -> SPI0数据输入 | D4: {=VLOOKUP($B4&$F4,IF({1,0},'1.管脚信息表'!$I:$I&'1.管脚信息表'!$H:$H,'1.管脚信息表'!$J:$J),2,0)} -> I | E4: {=VLOOKUP($B4&$F4,IF({1,0},'1.管脚信息表'!$I:$I&'1.管脚信息表'!$H:$H,'1.管脚信息表'!$C:$C),2,0)} -> SPI0_SDI / I2S1_SDI / GPIO108 / UART6_RX / PWM5 / IIC8_SCL / CAM_VS0 | F4: 0 | G4: {=VLOOKUP($B4&$F4,IF({1,0},'1.管脚信息表'!$I:$I&'1.管脚信息表'!$H:$H,'1.管脚信息表'!$G:$G),2,0)} -> REG_SPI0_SDI
B5: SPI0_CS_X | C5: {=VLOOKUP($B5&$F5,IF({1,0},'1.管脚信息表'!$I:$I&'1.管脚信息表'!$H:$H,'1.管脚信息表'!$K:$K),2,0)} -> SPI0片选信号 | D5: {=VLOOKUP($B5&$F5,IF({1,0},'1.管脚信息表'!$I:$I&'1.管脚信息表'!$H:$H,'1.管脚信息表'!$J:$J),2,0)} -> O | E5: {=VLOOKUP($B5&$F5,IF({1,0},'1.管脚信息表'!$I:$I&'1.管脚信息表'!$H:$H,'1.管脚信息表'!$C:$C),2,0)} -> SPI0_CS_X / I2S1_WSI / GPIO107 / UART6_TX / PWM4 / IIC8_SDA / CAM_HS0 | F5: 0 | G5: {=VLOOKUP($B5&$F5,IF({1,0},'1.管脚信息表'!$I:$I&'1.管脚信息表'!$H:$H,'1.管脚信息表'!$G:$G),2,0)} -> REG_SPI0_CS_X
A6: UART0 | B6: UART0_TX | C6: {=VLOOKUP($B6&$F6,IF({1,0},'1.管脚信息表'!$I:$I&'1.管脚信息表'!$H:$H,'1.管脚信息表'!$K:$K),2,0)} -> 串口0输出信号，DEBUG串口 | D6: {=VLOOKUP($B6&$F6,IF({1,0},'1.管脚信息表'!$I:$I&'1.管脚信息表'!$H:$H,'1.管脚信息表'!$J:$J),2,0)} -> O | E6: {=VLOOKUP($B6&$F6,IF({1,0},'1.管脚信息表'!$I:$I&'1.管脚信息表'!$H:$H,'1.管脚信息表'!$C:$C),2,0)} -> UART0_TX / GPIO81 | F6: 0 | G6: {=VLOOKUP($B6&$F6,IF({1,0},'1.管脚信息表'!$I:$I&'1.管脚信息表'!$H:$H,'1.管脚信息表'!$G:$G),2,0)} -> REG_UART0_TX
B7: UART0_RX | C7: {=VLOOKUP($B7&$F7,IF({1,0},'1.管脚信息表'!$I:$I&'1.管脚信息表'!$H:$H,'1.管脚信息表'!$K:$K),2,0)} -> 串口0输入信号，DEBUG串口 | D7: {=VLOOKUP($B7&$F7,IF({1,0},'1.管脚信息表'!$I:$I&'1.管脚信息表'!$H:$H,'1.管脚信息表'!$J:$J),2,0)} -> I | E7: {=VLOOKUP($B7&$F7,IF({1,0},'1.管脚信息表'!$I:$I&'1.管脚信息表'!$H:$H,'1.管脚信息表'!$C:$C),2,0)} -> UART0_RX / GPIO82 | F7: 0 | G7: {=VLOOKUP($B7&$F7,IF({1,0},'1.管脚信息表'!$I:$I&'1.管脚信息表'!$H:$H,'1.管脚信息表'!$G:$G),2,0)} -> REG_UART0_RX
A8: UART1 | B8: UART1_TX | C8: {=VLOOKUP($B8&$F8,IF({1,0},'1.管脚信息表'!$I:$I&'1.管脚信息表'!$H:$H,'1.管脚信息表'!$K:$K),2,0)} -> 串口5数据输入 | D8: {=VLOOKUP($B8&$F8,IF({1,0},'1.管脚信息表'!$I:$I&'1.管脚信息表'!$H:$H,'1.管脚信息表'!$J:$J),2,0)} -> I | E8: {=VLOOKUP($B8&$F8,IF({1,0},'1.管脚信息表'!$I:$I&'1.管脚信息表'!$H:$H,'1.管脚信息表'!$C:$C),2,0)} -> UART1_TX / DBG_IIC_SCL / GPIO83 | F8: 0 | G8: {=VLOOKUP($B8&$F8,IF({1,0},'1.管脚信息表'!$I:$I&'1.管脚信息表'!$H:$H,'1.管脚信息表'!$G:$G),2,0)} -> REG_UART1_TX
B9: UART1_RX | C9: {=VLOOKUP($B9&$F9,IF({1,0},'1.管脚信息表'!$I:$I&'1.管脚信息表'!$H:$H,'1.管脚信息表'!$K:$K),2,0)} -> 串口1输入信号 | D9: {=VLOOKUP($B9&$F9,IF({1,0},'1.管脚信息表'!$I:$I&'1.管脚信息表'!$H:$H,'1.管脚信息表'!$J:$J),2,0)} -> I | E9: {=VLOOKUP($B9&$F9,IF({1,0},'1.管脚信息表'!$I:$I&'1.管脚信息表'!$H:$H,'1.管脚信息表'!$C:$C),2,0)} -> UART1_RX / DBG_IIC_SDA / GPIO84 | F9: 0 | G9: {=VLOOKUP($B9&$F9,IF({1,0},'1.管脚信息表'!$I:$I&'1.管脚信息表'!$H:$H,'1.管脚信息表'!$G:$G),2,0)} -> REG_UART1_RX
B10: UART1_CTS | C10: {=VLOOKUP($B10&$F10,IF({1,0},'1.管脚信息表'!$I:$I&'1.管脚信息表'!$H:$H,'1.管脚信息表'!$K:$K),2,0)} -> 串口1发送清除信号 | D10: {=VLOOKUP($B10&$F10,IF({1,0},'1.管脚信息表'!$I:$I&'1.管脚信息表'!$H:$H,'1.管脚信息表'!$J:$J),2,0)} -> I | E10: {=VLOOKUP($B10&$F10,IF({1,0},'1.管脚信息表'!$I:$I&'1.管脚信息表'!$H:$H,'1.管脚信息表'!$C:$C),2,0)} -> UART1_CTS / GPIO86 / UART5_RX | F10: 0 | G10: {=VLOOKUP($B10&$F10,IF({1,0},'1.管脚信息表'!$I:$I&'1.管脚信息表'!$H:$H,'1.管脚信息表'!$G:$G),2,0)} -> REG_UART1_CTS
B11: UART1_RTS | C11: {=VLOOKUP($B11&$F11,IF({1,0},'1.管脚信息表'!$I:$I&'1.管脚信息表'!$H:$H,'1.管脚信息表'!$K:$K),2,0)} -> 串口1发送请求信号 | D11: {=VLOOKUP($B11&$F11,IF({1,0},'1.管脚信息表'!$I:$I&'1.管脚信息表'!$H:$H,'1.管脚信息表'!$J:$J),2,0)} -> O | E11: {=VLOOKUP($B11&$F11,IF({1,0},'1.管脚信息表'!$I:$I&'1.管脚信息表'!$H:$H,'1.管脚信息表'!$C:$C),2,0)} -> UART1_RTS / GPIO85 / UART5_TX | F11: 0 | G11: {=VLOOKUP($B11&$F11,IF({1,0},'1.管脚信息表'!$I:$I&'1.管脚信息表'!$H:$H,'1.管脚信息表'!$G:$G),2,0)} -> REG_UART1_RTS
A12: UART4 | B12: UART4_TX | C12: {=VLOOKUP($B12&$F12,IF({1,0},'1.管脚信息表'!$I:$I&'1.管脚信息表'!$H:$H,'1.管脚信息表'!$K:$K),2,0)} -> 串口4数据输出 | D12: {=VLOOKUP($B12&$F12,IF({1,0},'1.管脚信息表'!$I:$I&'1.管脚信息表'!$H:$H,'1.管脚信息表'!$J:$J),2,0)} -> O | E12: {=VLOOKUP($B12&$F12,IF({1,0},'1.管脚信息表'!$I:$I&'1.管脚信息表'!$H:$H,'1.管脚信息表'!$C:$C),2,0)} -> UART4_TX / SD2_1_CLK / GPIO91 / UART1_RTS / SPI3_SCK / IIC8_SDA / KEY_ROW0 | F12: 0 | G12: {=VLOOKUP($B12&$F12,IF({1,0},'1.管脚信息表'!$I:$I&'1.管脚信息表'!$H:$H,'1.管脚信息表'!$G:$G),2,0)} -> REG_UART4_TX
B13: UART4_RX | C13: {=VLOOKUP($B13&$F13,IF({1,0},'1.管脚信息表'!$I:$I&'1.管脚信息表'!$H:$H,'1.管脚信息表'!$K:$K),2,0)} -> 串口4数据输入 | D13: {=VLOOKUP($B13&$F13,IF({1,0},'1.管脚信息表'!$I:$I&'1.管脚信息表'!$H:$H,'1.管脚信息表'!$J:$J),2,0)} -> I | E13: {=VLOOKUP($B13&$F13,IF({1,0},'1.管脚信息表'!$I:$I&'1.管脚信息表'!$H:$H,'1.管脚信息表'!$C:$C),2,0)} -> UART4_RX / SD2_1_CMD / GPIO92 / UART1_CTS / SPI3_SDO / IIC8_SCL / KEY_ROW1 | F13: 0 | G13: {=VLOOKUP($B13&$F13,IF({1,0},'1.管脚信息表'!$I:$I&'1.管脚信息表'!$H:$H,'1.管脚信息表'!$G:$G),2,0)} -> REG_UART4_RX
B14: UART4_CTS | C14: {=VLOOKUP($B14&$F14,IF({1,0},'1.管脚信息表'!$I:$I&'1.管脚信息表'!$H:$H,'1.管脚信息表'!$K:$K),2,0)} -> 串口4发送清除信号 | D14: {=VLOOKUP($B14&$F14,IF({1,0},'1.管脚信息表'!$I:$I&'1.管脚信息表'!$H:$H,'1.管脚信息表'!$J:$J),2,0)} -> I | E14: {=VLOOKUP($B14&$F14,IF({1,0},'1.管脚信息表'!$I:$I&'1.管脚信息表'!$H:$H,'1.管脚信息表'!$C:$C),2,0)} -> UART4_CTS / GPIO94 / UART3_CTS / SPI3_CS_X / IIC9_SCL / KEY_ROW3 | F14: 0 | G14: {=VLOOKUP($B14&$F14,IF({1,0},'1.管脚信息表'!$I:$I&'1.管脚信息表'!$H:$H,'1.管脚信息表'!$G:$G),2,0)} -> REG_UART4_CTS
B15: UART4_RTS | C15: {=VLOOKUP($B15&$F15,IF({1,0},'1.管脚信息表'!$I:$I&'1.管脚信息表'!$H:$H,'1.管脚信息表'!$K:$K),2,0)} -> 串口4发送请求信号 | D15: {=VLOOKUP($B15&$F15,IF({1,0},'1.管脚信息表'!$I:$I&'1.管脚信息表'!$H:$H,'1.管脚信息表'!$J:$J),2,0)} -> O | E15: {=VLOOKUP($B15&$F15,IF({1,0},'1.管脚信息表'!$I:$I&'1.管脚信息表'!$H:$H,'1.管脚信息表'!$C:$C),2,0)} -> UART4_RTS / GPIO93 / UART3_RTS / SPI3_SDI / IIC9_SDA / KEY_ROW2 | F15: 0 | G15: {=VLOOKUP($B15&$F15,IF({1,0},'1.管脚信息表'!$I:$I&'1.管脚信息表'!$H:$H,'1.管脚信息表'!$G:$G),2,0)} -> REG_UART4_RTS
A16: I2S0 | B16: I2S0_MCLK | C16: {=VLOOKUP($B16&$F16,IF({1,0},'1.管脚信息表'!$I:$I&'1.管脚信息表'!$H:$H,'1.管脚信息表'!$K:$K),2,0)} -> I2S0或PCM0接口主时钟，可以作为音频CODEC的工作时钟 | D16: {=VLOOKUP($B16&$F16,IF({1,0},'1.管脚信息表'!$I:$I&'1.管脚信息表'!$H:$H,'1.管脚信息表'!$J:$J),2,0)} -> O | E16: {=VLOOKUP($B16&$F16,IF({1,0},'1.管脚信息表'!$I:$I&'1.管脚信息表'!$H:$H,'1.管脚信息表'!$C:$C),2,0)} -> I2S0_MCLK / PWM5 / GPIO5 / UART7_RX / CAM_VS2 | F16: 0 | G16: {=VLOOKUP($B16&$F16,IF({1,0},'1.管脚信息表'!$I:$I&'1.管脚信息表'!$H:$H,'1.管脚信息表'!$G:$G),2,0)} -> REG_I2S0_MCLK
B17: I2S0_SCLK | C17: {=VLOOKUP($B17&$F17,IF({1,0},'1.管脚信息表'!$I:$I&'1.管脚信息表'!$H:$H,'1.管脚信息表'!$K:$K),2,0)} -> I2S0或PCM0时钟 | D17: {=VLOOKUP($B17&$F17,IF({1,0},'1.管脚信息表'!$I:$I&'1.管脚信息表'!$H:$H,'1.管脚信息表'!$J:$J),2,0)} -> O | E17: {=VLOOKUP($B17&$F17,IF({1,0},'1.管脚信息表'!$I:$I&'1.管脚信息表'!$H:$H,'1.管脚信息表'!$C:$C),2,0)} -> I2S0_SCLK / PWM0 / GPIO0 / UART5_TX / SPI0_CS_X / KEY_ROW0 / CAM_HS0 | F17: 0 | G17: {=VLOOKUP($B17&$F17,IF({1,0},'1.管脚信息表'!$I:$I&'1.管脚信息表'!$H:$H,'1.管脚信息表'!$G:$G),2,0)} -> REG_I2S0_SCLK
B18: I2S0_WSI | C18: {=VLOOKUP($B18&$F18,IF({1,0},'1.管脚信息表'!$I:$I&'1.管脚信息表'!$H:$H,'1.管脚信息表'!$K:$K),2,0)} -> I2S0左右声道选择信号，或PCM0帧同步信号 | D18: {=VLOOKUP($B18&$F18,IF({1,0},'1.管脚信息表'!$I:$I&'1.管脚信息表'!$H:$H,'1.管脚信息表'!$J:$J),2,0)} -> IO | E18: {=VLOOKUP($B18&$F18,IF({1,0},'1.管脚信息表'!$I:$I&'1.管脚信息表'!$H:$H,'1.管脚信息表'!$C:$C),2,0)} -> I2S0_WSI / PWM1 / GPIO1 / UART5_RX / SPI0_SDI / KEY_ROW1 / CAM_VS0 | F18: 0 | G18: {=VLOOKUP($B18&$F18,IF({1,0},'1.管脚信息表'!$I:$I&'1.管脚信息表'!$H:$H,'1.管脚信息表'!$G:$G),2,0)} -> REG_I2S0_WSI
B19: I2S0_SDO | C19: {=VLOOKUP($B19&$F19,IF({1,0},'1.管脚信息表'!$I:$I&'1.管脚信息表'!$H:$H,'1.管脚信息表'!$K:$K),2,0)} -> I2S0或PCM0接口数据输出 | D19: {=VLOOKUP($B19&$F19,IF({1,0},'1.管脚信息表'!$I:$I&'1.管脚信息表'!$H:$H,'1.管脚信息表'!$J:$J),2,0)} -> O | E19: {=VLOOKUP($B19&$F19,IF({1,0},'1.管脚信息表'!$I:$I&'1.管脚信息表'!$H:$H,'1.管脚信息表'!$C:$C),2,0)} -> I2S0_SDO / PWM4 / GPIO4 / UART7_TX / CAM_HS2 | F19: 0 | G19: {=VLOOKUP($B19&$F19,IF({1,0},'1.管脚信息表'!$I:$I&'1.管脚信息表'!$H:$H,'1.管脚信息表'!$G:$G),2,0)} -> REG_I2S0_SDO
B20: I2S0_SDI0 | C20: {=VLOOKUP($B20&$F20,IF({1,0},'1.管脚信息表'!$I:$I&'1.管脚信息表'!$H:$H,'1.管脚信息表'!$K:$K),2,0)} -> I2S0或PCM0接口数据输入0 | D20: {=VLOOKUP($B20&$F20,IF({1,0},'1.管脚信息表'!$I:$I&'1.管脚信息表'!$H:$H,'1.管脚信息表'!$J:$J),2,0)} -> I | E20: {=VLOOKUP($B20&$F20,IF({1,0},'1.管脚信息表'!$I:$I&'1.管脚信息表'!$H:$H,'1.管脚信息表'!$C:$C),2,0)} -> I2S0_SDI0 / PWM2 / GPIO2 / UART6_TX / SPI0_SDO / KEY_ROW2 / CAM_HS1 | F20: 0 | G20: {=VLOOKUP($B20&$F20,IF({1,0},'1.管脚信息表'!$I:$I&'1.管脚信息表'!$H:$H,'1.管脚信息表'!$G:$G),2,0)} -> REG_I2S0_SDI0
B21: I2S0_SDI1 | C21: {=VLOOKUP($B21&$F21,IF({1,0},'1.管脚信息表'!$I:$I&'1.管脚信息表'!$H:$H,'1.管脚信息表'!$K:$K),2,0)} -> I2S0或PCM0接口数据输入1 | D21: {=VLOOKUP($B21&$F21,IF({1,0},'1.管脚信息表'!$I:$I&'1.管脚信息表'!$H:$H,'1.管脚信息表'!$J:$J),2,0)} -> I | E21: {=VLOOKUP($B21&$F21,IF({1,0},'1.管脚信息表'!$I:$I&'1.管脚信息表'!$H:$H,'1.管脚信息表'!$C:$C),2,0)} -> I2S0_SDI1 / PWM3 / GPIO3 / UART6_RX / SPI0_SCK / KEY_ROW3 / CAM_VS1 | F21: 0 | G21: {=VLOOKUP($B21&$F21,IF({1,0},'1.管脚信息表'!$I:$I&'1.管脚信息表'!$H:$H,'1.管脚信息表'!$G:$G),2,0)} -> REG_I2S0_SDI1
A22: EMMC | B22: EMMC_CLK | C22: {=VLOOKUP($B22&$F22,IF({1,0},'1.管脚信息表'!$I:$I&'1.管脚信息表'!$H:$H,'1.管脚信息表'!$K:$K),2,0)} -> EMMC时钟输出信号 | D22: {=VLOOKUP($B22&$F22,IF({1,0},'1.管脚信息表'!$I:$I&'1.管脚信息表'!$H:$H,'1.管脚信息表'!$J:$J),2,0)} -> O | E22: {=VLOOKUP($B22&$F22,IF({1,0},'1.管脚信息表'!$I:$I&'1.管脚信息表'!$H:$H,'1.管脚信息表'!$C:$C),2,0)} -> EMMC_CLK / SPINOR_SCK / SPINAND_SCK | F22: 0 | G22: {=VLOOKUP($B22&$F22,IF({1,0},'1.管脚信息表'!$I:$I&'1.管脚信息表'!$H:$H,'1.管脚信息表'!$G:$G),2,0)} -> REG_EMMC_CLK
B23: EMMC_CMD | C23: {=VLOOKUP($B23&$F23,IF({1,0},'1.管脚信息表'!$I:$I&'1.管脚信息表'!$H:$H,'1.管脚信息表'!$K:$K),2,0)} -> EMMC命令信号 | D23: {=VLOOKUP($B23&$F23,IF({1,0},'1.管脚信息表'!$I:$I&'1.管脚信息表'!$H:$H,'1.管脚信息表'!$J:$J),2,0)} -> B | E23: {=VLOOKUP($B23&$F23,IF({1,0},'1.管脚信息表'!$I:$I&'1.管脚信息表'!$H:$H,'1.管脚信息表'!$C:$C),2,0)} -> EMMC_CMD / SPINOR_SDI / SPINADN_SDI | F23: 0 | G23: {=VLOOKUP($B23&$F23,IF({1,0},'1.管脚信息表'!$I:$I&'1.管脚信息表'!$H:$H,'1.管脚信息表'!$G:$G),2,0)} -> REG_EMMC_CMD
B24: EMMC_RST_X | C24: {=VLOOKUP($B24&$F24,IF({1,0},'1.管脚信息表'!$I:$I&'1.管脚信息表'!$H:$H,'1.管脚信息表'!$K:$K),2,0)} -> EMMC复位信号 | D24: {=VLOOKUP($B24&$F24,IF({1,0},'1.管脚信息表'!$I:$I&'1.管脚信息表'!$H:$H,'1.管脚信息表'!$J:$J),2,0)} -> O | E24: {=VLOOKUP($B24&$F24,IF({1,0},'1.管脚信息表'!$I:$I&'1.管脚信息表'!$H:$H,'1.管脚信息表'!$C:$C),2,0)} -> EMMC_RST_X | F24: 0 | G24: {=VLOOKUP($B24&$F24,IF({1,0},'1.管脚信息表'!$I:$I&'1.管脚信息表'!$H:$H,'1.管脚信息表'!$G:$G),2,0)} -> REG_EMMC_RST_X
B25: EMMC_D0 | C25: {=VLOOKUP($B25&$F25,IF({1,0},'1.管脚信息表'!$I:$I&'1.管脚信息表'!$H:$H,'1.管脚信息表'!$K:$K),2,0)} -> EMMC数据信号0 | D25: {=VLOOKUP($B25&$F25,IF({1,0},'1.管脚信息表'!$I:$I&'1.管脚信息表'!$H:$H,'1.管脚信息表'!$J:$J),2,0)} -> B | E25: {=VLOOKUP($B25&$F25,IF({1,0},'1.管脚信息表'!$I:$I&'1.管脚信息表'!$H:$H,'1.管脚信息表'!$C:$C),2,0)} -> EMMC_D0 / SPINOR_SDO / SPINAND_SDO | F25: 0 | G25: {=VLOOKUP($B25&$F25,IF({1,0},'1.管脚信息表'!$I:$I&'1.管脚信息表'!$H:$H,'1.管脚信息表'!$G:$G),2,0)} -> REG_EMMC_D0
B26: EMMC_D1 | C26: {=VLOOKUP($B26&$F26,IF({1,0},'1.管脚信息表'!$I:$I&'1.管脚信息表'!$H:$H,'1.管脚信息表'!$K:$K),2,0)} -> EMMC数据信号1 | D26: {=VLOOKUP($B26&$F26,IF({1,0},'1.管脚信息表'!$I:$I&'1.管脚信息表'!$H:$H,'1.管脚信息表'!$J:$J),2,0)} -> B | E26: {=VLOOKUP($B26&$F26,IF({1,0},'1.管脚信息表'!$I:$I&'1.管脚信息表'!$H:$H,'1.管脚信息表'!$C:$C),2,0)} -> EMMC_D1 / SPINOR_CS_X / SPINAND_CS_X | F26: 0 | G26: {=VLOOKUP($B26&$F26,IF({1,0},'1.管脚信息表'!$I:$I&'1.管脚信息表'!$H:$H,'1.管脚信息表'!$G:$G),2,0)} -> REG_EMMC_D1
B27: EMMC_D2 | C27: {=VLOOKUP($B27&$F27,IF({1,0},'1.管脚信息表'!$I:$I&'1.管脚信息表'!$H:$H,'1.管脚信息表'!$K:$K),2,0)} -> EMMC数据信号2 | D27: {=VLOOKUP($B27&$F27,IF({1,0},'1.管脚信息表'!$I:$I&'1.管脚信息表'!$H:$H,'1.管脚信息表'!$J:$J),2,0)} -> B | E27: {=VLOOKUP($B27&$F27,IF({1,0},'1.管脚信息表'!$I:$I&'1.管脚信息表'!$H:$H,'1.管脚信息表'!$C:$C),2,0)} -> EMMC_D2 / SPINOR_HOLD_X / SPINAND_HOLD_X | F27: 0 | G27: {=VLOOKUP($B27&$F27,IF({1,0},'1.管脚信息表'!$I:$I&'1.管脚信息表'!$H:$H,'1.管脚信息表'!$G:$G),2,0)} -> REG_EMMC_D2
B28: EMMC_D3 | C28: {=VLOOKUP($B28&$F28,IF({1,0},'1.管脚信息表'!$I:$I&'1.管脚信息表'!$H:$H,'1.管脚信息表'!$K:$K),2,0)} -> EMMC数据信号3 | D28: {=VLOOKUP($B28&$F28,IF({1,0},'1.管脚信息表'!$I:$I&'1.管脚信息表'!$H:$H,'1.管脚信息表'!$J:$J),2,0)} -> B | E28: {=VLOOKUP($B28&$F28,IF({1,0},'1.管脚信息表'!$I:$I&'1.管脚信息表'!$H:$H,'1.管脚信息表'!$C:$C),2,0)} -> EMMC_D3 / SPINOR_WP_X / SPINAND_WP_X | F28: 0 | G28: {=VLOOKUP($B28&$F28,IF({1,0},'1.管脚信息表'!$I:$I&'1.管脚信息表'!$H:$H,'1.管脚信息表'!$G:$G),2,0)} -> REG_EMMC_D3
A29: SD0 | B29: SD0_CD_X | C29: {=VLOOKUP($B29&$F29,IF({1,0},'1.管脚信息表'!$I:$I&'1.管脚信息表'!$H:$H,'1.管脚信息表'!$K:$K),2,0)} -> SDIO端口0检测信号 | D29: {=VLOOKUP($B29&$F29,IF({1,0},'1.管脚信息表'!$I:$I&'1.管脚信息表'!$H:$H,'1.管脚信息表'!$J:$J),2,0)} -> I | E29: {=VLOOKUP($B29&$F29,IF({1,0},'1.管脚信息表'!$I:$I&'1.管脚信息表'!$H:$H,'1.管脚信息表'!$C:$C),2,0)} -> SD0_CD_X / PWM6 / DEBUG_0 / GPIO53 / IIC0_SDA | F29: 0 | G29: {=VLOOKUP($B29&$F29,IF({1,0},'1.管脚信息表'!$I:$I&'1.管脚信息表'!$H:$H,'1.管脚信息表'!$G:$G),2,0)} -> REG_SD0_CD_X
B30: SD0_CLK | C30: {=VLOOKUP($B30&$F30,IF({1,0},'1.管脚信息表'!$I:$I&'1.管脚信息表'!$H:$H,'1.管脚信息表'!$K:$K),2,0)} -> SDIO端口0时钟 | D30: {=VLOOKUP($B30&$F30,IF({1,0},'1.管脚信息表'!$I:$I&'1.管脚信息表'!$H:$H,'1.管脚信息表'!$J:$J),2,0)} -> O | E30: {=VLOOKUP($B30&$F30,IF({1,0},'1.管脚信息表'!$I:$I&'1.管脚信息表'!$H:$H,'1.管脚信息表'!$C:$C),2,0)} -> SD0_CLK / PWM7 / DEBUG_1 / GPIO54 / SPI3_SDO / IIC1_SDA | F30: 0 | G30: {=VLOOKUP($B30&$F30,IF({1,0},'1.管脚信息表'!$I:$I&'1.管脚信息表'!$H:$H,'1.管脚信息表'!$G:$G),2,0)} -> REG_SD0_CLK
B31: SD0_PWR_EN | C31: {=VLOOKUP($B31&$F31,IF({1,0},'1.管脚信息表'!$I:$I&'1.管脚信息表'!$H:$H,'1.管脚信息表'!$K:$K),2,0)} -> SDIO端口0 PWR使能信号 | D31: {=VLOOKUP($B31&$F31,IF({1,0},'1.管脚信息表'!$I:$I&'1.管脚信息表'!$H:$H,'1.管脚信息表'!$J:$J),2,0)} -> O | E31: {=VLOOKUP($B31&$F31,IF({1,0},'1.管脚信息表'!$I:$I&'1.管脚信息表'!$H:$H,'1.管脚信息表'!$C:$C),2,0)} -> SD0_PWR_EN / PWM13 / DEBUG_7 / GPIO60 / IIC0_SCL | F31: 0 | G31: {=VLOOKUP($B31&$F31,IF({1,0},'1.管脚信息表'!$I:$I&'1.管脚信息表'!$H:$H,'1.管脚信息表'!$G:$G),2,0)} -> REG_SD0_PWR_EN
B32: SD0_CMD | C32: {=VLOOKUP($B32&$F32,IF({1,0},'1.管脚信息表'!$I:$I&'1.管脚信息表'!$H:$H,'1.管脚信息表'!$K:$K),2,0)} -> SDIO端口0命令信号 | D32: {=VLOOKUP($B32&$F32,IF({1,0},'1.管脚信息表'!$I:$I&'1.管脚信息表'!$H:$H,'1.管脚信息表'!$J:$J),2,0)} -> B | E32: {=VLOOKUP($B32&$F32,IF({1,0},'1.管脚信息表'!$I:$I&'1.管脚信息表'!$H:$H,'1.管脚信息表'!$C:$C),2,0)} -> SD0_CMD / PWM8 / DEBUG_2 / GPIO55 / SPI3_SDI / IIC1_SCL | F32: 0 | G32: {=VLOOKUP($B32&$F32,IF({1,0},'1.管脚信息表'!$I:$I&'1.管脚信息表'!$H:$H,'1.管脚信息表'!$G:$G),2,0)} -> REG_SD0_CMD
B33: SD0_D0 | C33: {=VLOOKUP($B33&$F33,IF({1,0},'1.管脚信息表'!$I:$I&'1.管脚信息表'!$H:$H,'1.管脚信息表'!$K:$K),2,0)} -> SDIO端口0数据0 | D33: {=VLOOKUP($B33&$F33,IF({1,0},'1.管脚信息表'!$I:$I&'1.管脚信息表'!$H:$H,'1.管脚信息表'!$J:$J),2,0)} -> B | E33: {=VLOOKUP($B33&$F33,IF({1,0},'1.管脚信息表'!$I:$I&'1.管脚信息表'!$H:$H,'1.管脚信息表'!$C:$C),2,0)} -> SD0_D0 / PWM9 / DEBUG_3 / GPIO56 / SPI0_SCK / SPI3_CS_X / IIC2_SDA | F33: 0 | G33: {=VLOOKUP($B33&$F33,IF({1,0},'1.管脚信息表'!$I:$I&'1.管脚信息表'!$H:$H,'1.管脚信息表'!$G:$G),2,0)} -> REG_SD0_D0
B34: SD0_D1 | C34: {=VLOOKUP($B34&$F34,IF({1,0},'1.管脚信息表'!$I:$I&'1.管脚信息表'!$H:$H,'1.管脚信息表'!$K:$K),2,0)} -> SDIO端口0数据1 | D34: {=VLOOKUP($B34&$F34,IF({1,0},'1.管脚信息表'!$I:$I&'1.管脚信息表'!$H:$H,'1.管脚信息表'!$J:$J),2,0)} -> B | E34: {=VLOOKUP($B34&$F34,IF({1,0},'1.管脚信息表'!$I:$I&'1.管脚信息表'!$H:$H,'1.管脚信息表'!$C:$C),2,0)} -> SD0_D1 / PWM10/ DEBUG_4 / GPIO57 / SPI3_SCK / SPI0_CS_X / IIC2_SCL | F34: 0 | G34: {=VLOOKUP($B34&$F34,IF({1,0},'1.管脚信息表'!$I:$I&'1.管脚信息表'!$H:$H,'1.管脚信息表'!$G:$G),2,0)} -> REG_SD0_D1
B35: SD0_D2 | C35: {=VLOOKUP($B35&$F35,IF({1,0},'1.管脚信息表'!$I:$I&'1.管脚信息表'!$H:$H,'1.管脚信息表'!$K:$K),2,0)} -> SDIO端口0数据2 | D35: {=VLOOKUP($B35&$F35,IF({1,0},'1.管脚信息表'!$I:$I&'1.管脚信息表'!$H:$H,'1.管脚信息表'!$J:$J),2,0)} -> B | E35: {=VLOOKUP($B35&$F35,IF({1,0},'1.管脚信息表'!$I:$I&'1.管脚信息表'!$H:$H,'1.管脚信息表'!$C:$C),2,0)} -> SD0_D2 / PWM11 / DEBUG_5 / GPIO58 / SPI0_SDI / IIC3_SDA | F35: 0 | G35: {=VLOOKUP($B35&$F35,IF({1,0},'1.管脚信息表'!$I:$I&'1.管脚信息表'!$H:$H,'1.管脚信息表'!$G:$G),2,0)} -> REG_SD0_D2
B36: SD0_D3 | C36: {=VLOOKUP($B36&$F36,IF({1,0},'1.管脚信息表'!$I:$I&'1.管脚信息表'!$H:$H,'1.管脚信息表'!$K:$K),2,0)} -> SDIO端口0数据3 | D36: {=VLOOKUP($B36&$F36,IF({1,0},'1.管脚信息表'!$I:$I&'1.管脚信息表'!$H:$H,'1.管脚信息表'!$J:$J),2,0)} -> B | E36: {=VLOOKUP($B36&$F36,IF({1,0},'1.管脚信息表'!$I:$I&'1.管脚信息表'!$H:$H,'1.管脚信息表'!$C:$C),2,0)} -> SD0_D3 / PWM12 / DEBUG_6 / GPIO59 / SPI0_SDO / IIC3_SCL | F36: 0 | G36: {=VLOOKUP($B36&$F36,IF({1,0},'1.管脚信息表'!$I:$I&'1.管脚信息表'!$H:$H,'1.管脚信息表'!$G:$G),2,0)} -> REG_SD0_D3
A37: SD1 | B37: SD1_CD_X | C37: {=VLOOKUP($B37&$F37,IF({1,0},'1.管脚信息表'!$I:$I&'1.管脚信息表'!$H:$H,'1.管脚信息表'!$K:$K),2,0)} -> SDIO端口1检测信号 | D37: {=VLOOKUP($B37&$F37,IF({1,0},'1.管脚信息表'!$I:$I&'1.管脚信息表'!$H:$H,'1.管脚信息表'!$J:$J),2,0)} -> I | E37: {=VLOOKUP($B37&$F37,IF({1,0},'1.管脚信息表'!$I:$I&'1.管脚信息表'!$H:$H,'1.管脚信息表'!$C:$C),2,0)} -> SD1_CD_X / PWM14 / GPIO61 / CAM_MCLK0 / CAM_HS0 | F37: 0 | G37: {=VLOOKUP($B37&$F37,IF({1,0},'1.管脚信息表'!$I:$I&'1.管脚信息表'!$H:$H,'1.管脚信息表'!$G:$G),2,0)} -> REG_SD1_CD_X
B38: SD1_CLK | C38: {=VLOOKUP($B38&$F38,IF({1,0},'1.管脚信息表'!$I:$I&'1.管脚信息表'!$H:$H,'1.管脚信息表'!$K:$K),2,0)} -> SDIO端口1时钟 | D38: {=VLOOKUP($B38&$F38,IF({1,0},'1.管脚信息表'!$I:$I&'1.管脚信息表'!$H:$H,'1.管脚信息表'!$J:$J),2,0)} -> O | E38: {=VLOOKUP($B38&$F38,IF({1,0},'1.管脚信息表'!$I:$I&'1.管脚信息表'!$H:$H,'1.管脚信息表'!$C:$C),2,0)} -> SD1_CLK / PWM15 / GPIO62 / SPI2_SDO / IIC4_SDA / CAM_HS0 | F38: 0 | G38: {=VLOOKUP($B38&$F38,IF({1,0},'1.管脚信息表'!$I:$I&'1.管脚信息表'!$H:$H,'1.管脚信息表'!$G:$G),2,0)} -> REG_SD1_CLK
B39: SD1_PWR_EN | C39: {=VLOOKUP($B39&$F39,IF({1,0},'1.管脚信息表'!$I:$I&'1.管脚信息表'!$H:$H,'1.管脚信息表'!$K:$K),2,0)} -> SDIO端口1 PWR使能信号 | D39: {=VLOOKUP($B39&$F39,IF({1,0},'1.管脚信息表'!$I:$I&'1.管脚信息表'!$H:$H,'1.管脚信息表'!$J:$J),2,0)} -> O | E39: {=VLOOKUP($B39&$F39,IF({1,0},'1.管脚信息表'!$I:$I&'1.管脚信息表'!$H:$H,'1.管脚信息表'!$C:$C),2,0)} -> SD1_PWR_EN / PWM1 / GPIO68 / CAM_MCLK1 / CAM_VS2 | F39: 0 | G39: {=VLOOKUP($B39&$F39,IF({1,0},'1.管脚信息表'!$I:$I&'1.管脚信息表'!$H:$H,'1.管脚信息表'!$G:$G),2,0)} -> REG_SD1_PWR_EN
B40: SD1_CMD | C40: {=VLOOKUP($B40&$F40,IF({1,0},'1.管脚信息表'!$I:$I&'1.管脚信息表'!$H:$H,'1.管脚信息表'!$K:$K),2,0)} -> SDIO端口1命令信号 | D40: {=VLOOKUP($B40&$F40,IF({1,0},'1.管脚信息表'!$I:$I&'1.管脚信息表'!$H:$H,'1.管脚信息表'!$J:$J),2,0)} -> B | E40: {=VLOOKUP($B40&$F40,IF({1,0},'1.管脚信息表'!$I:$I&'1.管脚信息表'!$H:$H,'1.管脚信息表'!$C:$C),2,0)} -> SD1_CMD / PWM16 / GPIO63 / SPI2_SDI / IIC4_SCL / CAM_VS0 | F40: 0 | G40: {=VLOOKUP($B40&$F40,IF({1,0},'1.管脚信息表'!$I:$I&'1.管脚信息表'!$H:$H,'1.管脚信息表'!$G:$G),2,0)} -> REG_SD1_CMD
...

Sheet 3.管脚控制寄存器
A1: GROUP | B1: Register Name | C1: Pin Number | D1: Address | E1: Field Name | F1: Msb | G1: Lsb | H1: Bits | I1: Init | J1: r/w | K1: Field Description
A2: G1 | B2: REG_RGMII0_TXD0 | C2: W1 | D2: 0x28104100 | E2: reg_RGMII0_TXD0_PU_EN | F2: 2 | G2: 2 | H2: 1 | I2: h0 | J2: rw | K2: Pull Up Enable for RGMII0_TXD0
E3: reg_RGMII0_TXD0_PD_EN | F3: 3 | G3: 3 | H3: 1 | I3: h0 | J3: rw | K3: Pull Down Enable for RGMII0_TXD0
E4: reg_RGMII0_TXD0_PIN_SEL_EN | F4: 7 | G4: 4 | H4: 4 | I4: h0 | J4: rw | K4: Pin Mux Selector for RGMII0_TXD0
E5: reg_RGMII0_TXD0_DRI_SEL | F5: 11 | G5: 8 | H5: 4 | I5: h8 | J5: rw | K5: Driving Selector for RGMII0_TXD0
E6: reg_RGMII0_TXD0_SCT_EN | F6: 12 | G6: 12 | H6: 1 | I6: h0 | J6: rw | K6: Schmitt trigger enable for RGMII0_TXD0. '1' enables Schmitt trigger input function
E7: reg_RGMII0_TXD0_OEX_EN | F7: 13 | G7: 13 | H7: 1 | I7: h1 | J7: rw | K7: PAD OEX enable for RGMII0_TXD0. '1' enables PAD output mode under IP's drive
A8: G1 | B8: REG_RGMII0_TXD1 | C8: P1 | D8: 0x28104104 | E8: reg_RGMII0_TXD1_PU_EN | F8: 2 | G8: 2 | H8: 1 | I8: h0 | J8: rw | K8: Pull Up Enable for RGMII0_TXD1
E9: reg_RGMII0_TXD1_PD_EN | F9: 3 | G9: 3 | H9: 1 | I9: h0 | J9: rw | K9: Pull Down Enable for RGMII0_TXD1
E10: reg_RGMII0_TXD1_PIN_SEL_EN | F10: 7 | G10: 4 | H10: 4 | I10: h0 | J10: rw | K10: Pin Mux Selector for RGMII0_TXD1
E11: reg_RGMII0_TXD1_DRI_SEL | F11: 11 | G11: 8 | H11: 4 | I11: h8 | J11: rw | K11: Driving Selector for RGMII0_TXD1
E12: reg_RGMII0_TXD1_SCT_EN | F12: 12 | G12: 12 | H12: 1 | I12: h0 | J12: rw | K12: Schmitt trigger enable for RGMII0_TXD1. '1' enables Schmitt trigger input function
E13: reg_RGMII0_TXD1_OEX_EN | F13: 13 | G13: 13 | H13: 1 | I13: h1 | J13: rw | K13: PAD OEX enable for RGMII0_TXD1. '1' enables PAD output mode under IP's drive
A14: G1 | B14: REG_RGMII0_TXD2 | C14: R1 | D14: 0x28104108 | E14: reg_RGMII0_TXD2_PU_EN | F14: 2 | G14: 2 | H14: 1 | I14: h0 | J14: rw | K14: Pull Up Enable for RGMII0_TXD2
E15: reg_RGMII0_TXD2_PD_EN | F15: 3 | G15: 3 | H15: 1 | I15: h0 | J15: rw | K15: Pull Down Enable for RGMII0_TXD2
E16: reg_RGMII0_TXD2_PIN_SEL_EN | F16: 7 | G16: 4 | H16: 4 | I16: h0 | J16: rw | K16: Pin Mux Selector for RGMII0_TXD2
E17: reg_RGMII0_TXD2_DRI_SEL | F17: 11 | G17: 8 | H17: 4 | I17: h8 | J17: rw | K17: Driving Selector for RGMII0_TXD2
E18: reg_RGMII0_TXD2_SCT_EN | F18: 12 | G18: 12 | H18: 1 | I18: h0 | J18: rw | K18: Schmitt trigger enable for RGMII0_TXD2. '1' enables Schmitt trigger input function
E19: reg_RGMII0_TXD2_OEX_EN | F19: 13 | G19: 13 | H19: 1 | I19: h1 | J19: rw | K19: PAD OEX enable for RGMII0_TXD2. '1' enables PAD output mode under IP's drive
A20: G1 | B20: REG_RGMII0_TXD3 | C20: T1 | D20: 0x2810410C | E20: reg_RGMII0_TXD3_PU_EN | F20: 2 | G20: 2 | H20: 1 | I20: h0 | J20: rw | K20: Pull Up Enable for RGMII0_TXD3
E21: reg_RGMII0_TXD3_PD_EN | F21: 3 | G21: 3 | H21: 1 | I21: h0 | J21: rw | K21: Pull Down Enable for RGMII0_TXD3
E22: reg_RGMII0_TXD3_PIN_SEL_EN | F22: 7 | G22: 4 | H22: 4 | I22: h0 | J22: rw | K22: Pin Mux Selector for RGMII0_TXD3
E23: reg_RGMII0_TXD3_DRI_SEL | F23: 11 | G23: 8 | H23: 4 | I23: h8 | J23: rw | K23: Driving Selector for RGMII0_TXD3
E24: reg_RGMII0_TXD3_SCT_EN | F24: 12 | G24: 12 | H24: 1 | I24: h0 | J24: rw | K24: Schmitt trigger enable for RGMII0_TXD3. '1' enables Schmitt trigger input function
E25: reg_RGMII0_TXD3_OEX_EN | F25: 13 | G25: 13 | H25: 1 | I25: h1 | J25: rw | K25: PAD OEX enable for RGMII0_TXD3. '1' enables PAD output mode under IP's drive
A26: G1 | B26: REG_RGMII0_TXCTRL | C26: V1 | D26: 0x28104110 | E26: reg_RGMII0_TXCTRL_PU_EN | F26: 2 | G26: 2 | H26: 1 | I26: h0 | J26: rw | K26: Pull Up Enable for RGMII0_TXCTRL
E27: reg_RGMII0_TXCTRL_PD_EN | F27: 3 | G27: 3 | H27: 1 | I27: h0 | J27: rw | K27: Pull Down Enable for RGMII0_TXCTRL
E28: reg_RGMII0_TXCTRL_PIN_SEL_EN | F28: 7 | G28: 4 | H28: 4 | I28: h0 | J28: rw | K28: Pin Mux Selector for RGMII0_TXCTRL
E29: reg_RGMII0_TXCTRL_DRI_SEL | F29: 11 | G29: 8 | H29: 4 | I29: h8 | J29: rw | K29: Driving Selector for RGMII0_TXCTRL
E30: reg_RGMII0_TXCTRL_SCT_EN | F30: 12 | G30: 12 | H30: 1 | I30: h0 | J30: rw | K30: Schmitt trigger enable for RGMII0_TXCTRL. '1' enables Schmitt trigger input function
E31: reg_RGMII0_TXCTRL_OEX_EN | F31: 13 | G31: 13 | H31: 1 | I31: h1 | J31: rw | K31: PAD OEX enable for RGMII0_TXCTRL. '1' enables PAD output mode under IP's drive
A32: G1 | B32: REG_RGMII0_RXD0 | C32: U1 | D32: 0x28104114 | E32: reg_RGMII0_RXD0_PU_EN | F32: 2 | G32: 2 | H32: 1 | I32: h0 | J32: rw | K32: Pull Up Enable for RGMII0_RXD0
E33: reg_RGMII0_RXD0_PD_EN | F33: 3 | G33: 3 | H33: 1 | I33: h0 | J33: rw | K33: Pull Down Enable for RGMII0_RXD0
E34: reg_RGMII0_RXD0_PIN_SEL_EN | F34: 7 | G34: 4 | H34: 4 | I34: h0 | J34: rw | K34: Pin Mux Selector for RGMII0_RXD0
E35: reg_RGMII0_RXD0_DRI_SEL | F35: 11 | G35: 8 | H35: 4 | I35: h8 | J35: rw | K35: Driving Selector for RGMII0_RXD0
E36: reg_RGMII0_RXD0_SCT_EN | F36: 12 | G36: 12 | H36: 1 | I36: h0 | J36: rw | K36: Schmitt trigger enable for RGMII0_RXD0. '1' enables Schmitt trigger input function
E37: reg_RGMII0_RXD0_OEX_EN | F37: 13 | G37: 13 | H37: 1 | I37: h1 | J37: rw | K37: PAD OEX enable for RGMII0_RXD0. '1' enables PAD output mode under IP's drive
A38: G1 | B38: REG_RGMII0_RXD1 | C38: M1 | D38: 0x28104118 | E38: reg_RGMII0_RXD1_PU_EN | F38: 2 | G38: 2 | H38: 1 | I38: h0 | J38: rw | K38: Pull Up Enable for RGMII0_RXD1
E39: reg_RGMII0_RXD1_PD_EN | F39: 3 | G39: 3 | H39: 1 | I39: h0 | J39: rw | K39: Pull Down Enable for RGMII0_RXD1
E40: reg_RGMII0_RXD1_PIN_SEL_EN | F40: 7 | G40: 4 | H40: 4 | I40: h0 | J40: rw | K40: Pin Mux Selector for RGMII0_RXD1
...

Sheet 4.管脚默认状态
A1: Pin Name | B1: Default Function | C1: When the Core Power Is not Powered on and the I/O Power Is Powered on | E1: After the Core Power and I/O Power Are Powered on and Before the Reset Is Deasserted | G1: Chip Internal Pull-up/Pull-down Resistor
C2: Level State | D2: I/O type | E2: Level State | F2: I/O type
A3: LSADC_CH0 | B3: GPIO1_0 | C3: PD | D3: NA | E3: Z | F3: I | G3: RPD3 | I3: 电平状态说明： L:输出低电平； H:输出高电平； Z:高阻态； PU:输入态带内部上拉； PD:输入态带内部下拉； 内部上下拉电阻值： 请参考芯片手册第二章 DC/AC 电气参数部分。
A4: LSADC_CH1 | B4: GPIO1_1 | C4: PD | D4: NA | E4: Z | F4: I | G4: RPD3
A5: LSADC_CH2 | B5: GPIO1_2 | C5: PD | D5: NA | E5: Z | F5: I | G5: RPD3
A6: LSADC_CH3 | B6: GPIO1_3 | C6: PD | D6: NA | E6: Z | F6: I | G6: RPD3
A7: SYS_RSTN_OUT | B7: SYS_RSTN_OUT | C7: PD | D7: NA | E7: Z | F7: I | G7: RSPU1/RPU1/RPD1
A8: TEST_MODE | B8: TEST_MODE | C8: PD | D8: NA | E8: PD | F8: I | G8: RPD1
A9: RST_N | B9: RST_N | C9: PD | D9: NA | E9: PU | F9: I | G9: RPU1/RPD1
A10: POR_SEL | B10: POR_SEL | C10: PD | D10: NA | E10: PD | F10: I | G10: RPD1
A11: I2C0_SDA | B11: I2C0_SDA | C11: Z | D11: NA | E11: Z | F11: I
A12: I2C0_SCL | B12: I2C0_SCL | C12: Z | D12: NA | E12: Z | F12: I
A13: UART0_RXD | B13: GPIO1_4 | C13: PU | D13: NA | E13: PU | F13: I | G13: RSPU1/RPU1/RPD1
A14: UART0_TXD | B14: GPIO1_5 | C14: PD | D14: NA | E14: Z | F14: I | G14: RSPU1/RPU1/RPD1
A15: JTAG_TRSTN | B15: GPIO2_0 | C15: PD | D15: NA | E15: PD | F15: I | G15: RSPU1/RPU1/RPD1
A16: JTAG_TCK | B16: GPIO2_1 | C16: PD | D16: NA | E16: PD | F16: I | G16: RSPU1/RPU1/RPD1
A17: JTAG_TMS | B17: GPIO2_2 | C17: PD | D17: NA | E17: PU | F17: I | G17: RSPU1/RPU1/RPD1
A18: JTAG_TDO | B18: GPIO2_3 | C18: PD | D18: NA | E18: Z | F18: I | G18: RSPU1/RPU1/RPD1
A19: JTAG_TDI | B19: GPIO2_4 | C19: PD | D19: NA | E19: PU | F19: I | G19: RSPU1/RPU1/RPD1
A20: GPIO2_5 | B20: GPIO2_5 | C20: PD | D20: NA | E20: Z | F20: I | G20: RSPU1/RPU1/RPD1
A21: GPIO2_6 | B21: GPIO2_6 | C21: PD | D21: NA | E21: Z | F21: I | G21: RSPU1/RPU1/RPD1
A22: GPIO2_7 | B22: GPIO2_7 | C22: PD | D22: NA | E22: Z | F22: I | G22: RSPU1/RPU1/RPD1
A23: JTAG_EN | B23: JTAG_EN | C23: PD | D23: NA | E23: PD | F23: I | G23: RSPU1/RPU1/RPD1
A24: SPI0_SCLK | B24: GPIO3_0 | C24: PD | D24: NA | E24: Z | F24: I | G24: RSPU1/RPU1/RPD1
... A78: PCIE_CLK_REQ_N | B78: PCIE_CLK_REQ_N | C78: PD | D78: NA | E78: Z | F78: I | G78: RSPU1/RPU1/RPD1
A79: HDMI_HOTPLUG | B79: HDMI_HOTPLUG | C79: Z | D79: NA | E79: Z | F79: I
A80: HDMI_CEC | B80: HDMI_CEC | C80: Z | D80: NA | E80: Z | F80: I
A81: HDMI_SDA | B81: HDMI_SDA | C81: Z | D81: NA | E81: Z | F81: I
A82: HDMI_SCL | B82: HDMI_SCL | C82: Z | D82: NA | E82: Z | F82: I
A83: DSI_D3N | B83: GPIO13_0 | C83: 0 | D83: NA | E83: Z | F83: I
A84: DSI_D3P | B84: GPIO13_1 | C84: 0 | D84: NA | E84: Z | F84: I
A85: DSI_D1N | B85: GPIO13_2 | C85: 0 | D85: NA | E85: Z | F85: I
A86: DSI_D1P | B86: GPIO13_3 | C86: 0 | D86: NA | E86: Z | F86: I
A87: DSI_CKN | B87: GPIO13_4 | C87: 0 | D87: NA | E87: Z | F87: I
A88: DSI_CKP | B88: GPIO13_5 | C88: 0 | D88: NA | E88: Z | F88: I
A89: DSI_D0N | B89: GPIO13_6 | C89: 0 | D89: NA | E89: Z | F89: I
A90: DSI_D0P | B90: GPIO13_7 | C90: 0 | D90: NA | E90: Z | F90: I
A91: DSI_D2N | B91: GPIO9_6 | C91: 0 | D91: NA | E91: Z | F91: I
A92: DSI_D2P | B92: GPIO9_7 | C92: 0 | D92: NA | E92: Z | F92: I
A93: LCD_DATA0 | B93: GPIO0_0 | C93: Z | D93: NA | E93: Z | F93: I | G93: RSPU2/RPU2/RPD2
...

Sheet 4.管脚分布图
C1: 1 | D1: 2 | E1: 3 | F1: 4 | G1: 5 | H1: 6 | I1: 7 | J1: 8 | K1: 9 | L1: 10 | M1: 11 | N1: 12 | O1: 13 | P1: 14 | Q1: 15 | R1: 16 | S1: 17 | T1: 18 | U1: 19 | V1: 20 | W1: 21 | X1: 22 | Y1: 23 | Z1: 24 | AA1: 25 | AB1: 26 | AC1: 27 | AD1: 28 | AE1: 29 | AF1: 30 | AG1: 31 | AH1: 32 | AI1: 33 | AJ1: 34
B2: A | C2: VSSC | D2: AUX0 | E2: VSSC | F2: PWR_XTAL_XOUT | G2: VSSC | H2: MIPI0_TX4P | I2: MIPI0_TX3P | J2: MIPI0_TX2P | K2: MIPI0_TX1P | L2: MIPI0_TX0P | N2: AOUTL1 | O2: AOUTR1 | P2: AINR1_MIC | Q2: AINL1_MIC | S2: USB0_SSTXM | U2: USB0_DM | W2: USB1_REFCLK_M | Y2: USB1_SSRXM | Z2: VSSC | AA2: MIPI_RX16N | AB2: MIPI_RX14N | AC2: MIPI_RX12N | AD2: MIPI_RX10N | AE2: MIPI_RX8N | AF2: MIPI_RX6N | AG2: MIPI_RX5N | AH2: MIPI_RX4N | AI2: VSSC | AJ2: VSSC | AK2: A
B3: B | C3: HDMI_DDC_SCL | D3: HDMI_DDC_SDA | E3: SPK_EN | F3: PWR_XTAL_XIN | G3: VSSC | H3: MIPI0_TX4N | I3: MIPI0_TX3N | J3: MIPI0_TX2N | K3: MIPI0_TX1N | L3: MIPI0_TX0N | M3: VSSC | N3: AUDIO_VSS18A | O3: AUDIO_VSS18A | P3: AUDIO_VSS18A | Q3: AUDIO_VSS18A | R3: USB0_SSRXM | S3: USB0_SSTXP | T3: USB0_REFCLK_M | U3: USB0_DP | V3: USB1_DM | W3: USB1_REFCLK_P | X3: USB1_SSTXM | Y3: USB1_SSRXP | Z3: VSSC | AA3: MIPI_RX16P | AB3: MIPI_RX14P | AC3: MIPI_RX12P | AD3: MIPI_RX10P | AE3: MIPI_RX8P | AF3: MIPI_RX6P | AG3: MIPI_RX5P | AH3: MIPI_RX4P | AI3: MIPI_RX3P | AJ3: MIPI_RX3N | AK3: B
B4: C | C4: CAN0_RX | D4: CAN0_TX | E4: SD1_PWR_EN | F4: SD1_D2 | G4: CAM_MCLK2 | H4: VSSC | I4: VSSC | J4: VSSC | K4: VSSC | L4: VSSC | M4: VSSC | N4: AINR0_MIC | O4: AINL0_MIC | P4: AOUTL0 | Q4: AUDIO_VSS18A | R4: USB0_SSRXP | S4: VSSC | T4: USB0_REFCLK_P | U4: VSSC | V4: USB1_DP | W4: VSSC | X4: USB1_SSTXP | Y4: VSSC | Z4: VSSC | AA4: MIPI_RX17N | AB4: MIPI_RX15N | AC4: MIPI_RX13N | AD4: MIPI_RX11N | AE4: MIPI_RX9N | AF4: MIPI_RX7N | AG4: VSSC | AH4: VSSC | AI4: MIPI_RX2P | AJ4: MIPI_RX2N | AK4: C
B5: D | C5: GPIO3 | D5: GPIO7 | E5: SD1_CD_X | F5: SD1_D0 | G5: SD1_D3 | H5: CAM_MCLK3 | I5: CAM_MCLK4 | J5: PWM2 | K5: FAN0 | L5: FAN1 | M5: VSSC | N5: AUDIO_VSS18A | O5: AUDIO_VSS18A | P5: AUDIO_VSS18A | Q5: AOUTR0 | R5: VSSC | S5: SD0_CD_X | T5: VSSC | U5: SD0_PWR_EN | V5: VSSC | W5: SD0_CMD | X5: VSSC | Y5: SD0_D1 | Z5: VSSC | AA5: MIPI_RX17P | AB5: MIPI_RX15P | AC5: MIPI_RX13P | AD5: MIPI_RX11P | AE5: MIPI_RX9P | AF5: MIPI_RX7P | AG5: VSSC | AH5: VSSC | AI5: MIPI_RX1P | AJ5: MIPI_RX1N | AK5: D
B6: E | C6: GPIO4 | D6: GPIO6 | E6: EMMC_CMD | F6: SD1_CLK | G6: SD1_CMD | H6: SD1_D1 | I6: CAM_MCLK1 | J6: PWM0 | K6: PWM1 | L6: PWM3 | M6: VSSC | N6: SPI0_SCK | O6: SPI0_SDI | P6: SPI0_CS_X | Q6: VSSC | R6: VSSC | S6: SD0_D2 | T6: SD0_D3 | U6: SD0_D0 | V6: VSSC | W6: SD0_CLK | X6: PWR_GPIO1 | Y6: PTEST | Z6: VSSC | AA6: VSSC | AB6: VSSC | AC6: VSSC | AD6: VSSC | AE6: VSSC | AF6: VSSC | AG6: VSSC | AH6: VSSC | AI6: MIPI_RX0P | AJ6: MIPI_RX0N | AK6: E
B7: F | C7: GPIO1 | D7: GPIO5 | E7: UART1_RX | F7: UART1_CTS | G7: EMMC_CLK | H7: EMMC_D2 | I7: EMMC_D3 | J7: CAM_MCLK0 | K7: CAM_XLR0 | L7: VSSC | M7: VSSC | N7: SPI0_SDO | O7: VSSC | P7: VSSC | Q7: VSSC | R7: VSSC | S7: PWR_GPIO4 | T7: PWR_GPIO2 | U7: PWR_GPIO3 | V7: VSSC | W7: PWR_GPIO6 | X7: PWR_GPIO0 | Y7: PWR_GPIO5 | Z7: PWR_IIC_SCL | AA7: PWR_IIC_SDA | AB7: PWR_ON | AC7: PWR_BUTTON1 | AD7: PWR_SEQ1 | AE7: VSSC | AF7: PWR_WAKEUP1 | AG7: PWR_WAKEUP0 | AH7: VSSC | AI7: VSSC | AJ7: VSSC | AK7: F
B8: G | C8: GPIO2 | D8: GPIO0 | E8: UART1_RTS | F8: UART1_TX | G8: EMMC_RST_X | H8: EMMC_D0 | I8: VSSC | J8: VSSC | K8: CAM_MCLK5 | L8: CAM_XLR1 | M8: VSSC | N8: VSSC | O8: VSSC | P8: VSSC | Q8: VSSC | R8: VSSC | S8: VSSC | T8: VSSC | U8: VSSC | V8: VSSC | W8: VSSC | X8: VSSC | Y8: VSSC | Z8: VSSC | AA8: VSSC | AB8: VSSC | AC8: PWR_SEQ3 | AD8: PWR_SEQ2 | AE8: VSSC | AF8: PWR_UART_TX | AG8: PWR_UART_RX | AH8: VSSC | AI8: CLK_25M_SEL | AJ8: CLK_25M_OUT | AK8: G
B9: H | C9: IIC1_SDA | D9: IIC1_SCL | E9: UART0_TX | F9: UART0_RX | G9: IIC2_SCL | H9: EMMC_D1 | I9: VSSC | AD9: VSSC | AE9: VSSC | AF9: VSSC | AG9: VSSC | AH9: VSSC | AI9: PWR_RSTN | AJ9: VSSC | AK9: H
B10: J | C10: IIC0_SCL | D10: IIC2_SDA | E10: VSSC | F10: VSSC | G10: VSSC | H10: VSSC | I10: VSSC | K10: VDDC | L10: VSSC | M10: VDDC | N10: VSSC | O10: VDDIO18_2 | P10: VDDIO18_2 | Q10: VDDIO33_SD0 | R10: VSSC | S10: VDDIO18_RTC | T10: DSI0_VDD18A | U10: VSSC | V10: AUDIO_VSS18A | W10: AUDIO_VSS18A | X10: AUDIO_VDD18A | Y10: VSSC | Z10: USB_VP | AA10: VSSC | AB10: USB0_VBUS0 | AD10: USB_VPH | AE10: VSSC | AF10: USB0_RESREF | AG10: USB0_ID | AH10: VSSC | AI10: VSSC | AK10: J
B11: K | C11: RSTN | D11: IIC0_SDA | E11: TEMPSEN_BJT | F11: ADC1 | G11: IIC4_SDA | H11: IIC4_SCL | I11: VSSC | K11: VSSC | L11: VDDC | M11: VSSC | N11: VDDC | O11: VSSC | P11: VDDIO18_2 | Q11: VSSC | R11: VDDC_RTC | S11: VSSC | T11: DSI0_VDD18A | U11: DSI0_VDDA | V11: AUD0_AVREF | W11: AUDIO_VSS18A | X11: AUDIO_VDD18A | Y11: VSSC | Z11: USB_VP | AA11: VSSC | AB11: USB1_VBUS0 | AD11: USB_VPH | AE11: VSSC | AF11: USB1_RESREF | AG11: USB1_ID | AH11: VSSC | AI11: VSSC | AJ11: DDR1_DQ5 | AK11: K
B12: L | C12: VSSC | D12: RGMII0_RXCTRL | E12: RGMII1_RXD2 | F12: ADC2 | G12: ADC3 | H12: IIC5_SDA | I12: VSSC | J12: VSSC | K12: VDDC | L12: VSSC | M12: VDDC | N12: VSSC | O12: VDDC | P12: VSSC | Q12: VDDC | R12: VSSC | S12: VDDC_RTC | T12: VSSC | U12: VSSC | V12: VSSC | W12: AUD1_AVREF | X12: VSSC | Y12: VDDC | Z12: VSSC | AA12: VDDC | AB12: VSSC | AC12: VSSC | AD12: USB_VPH | AE12: VSSC | AF12: VSSC | AG12: VSSC | AH12: VSSC | AI12: DDR1_DM0 | AJ12: DDR1_DQ1 | AK12: L
B13: M | C13: RGMII0_RXD1 | D13: RGMII0_TXC | E13: RGMII1_RXD3 | F13: RGMII1_REFCLKO | G13: UART4_RX | H13: IIC5_SCL | I13: VSSC | J13: VDDIO33_EMMC | K13: VSSC | L13: VDDC | M13: VSSC | N13: VDDC | O13: VSSC | P13: VDDC | Q13: VSSC | R13: VDDC | S13: VSSC | T13: VDDC | U13: VSSC | V13: VDDC | W13: VSSC | X13: VDDC | Y13: VSSC | Z13: VDDC | AA13: VSSC | AB13: USB_DVDD | AC13: VSSC | AD13: VSSC | AE13: VSSC | AF13: DDR1_DQ3 | AG13: DDR1_DQS0_P | AH13: VSSC | AI13: DDR1_DQ7 | AJ13: DDR1_DQ6 | AK13: M
B14: N | C14: RGMII0_RXD2 | D14: RGMII0_RXC | E14: VSSC | F14: VSSC | G14: VSSC | H14: VSSC | I14: VSSC | J14: VSSC | K14: VDDC | L14: VSSC | M14: VDDC | N14: VSSC | O14: VDDC | P14: VSSC | Q14: VDDC | R14: VSSC | S14: VDDC | T14: VSSC | U14: VDDC | V14: VSSC | W14: VDDC | X14: VSSC | Y14: VDDC | Z14: VSSC | AA14: VDDC | AB14: USB_DVDD | AC14: CSI_VDDA | AD14: CSI_VDDA | AE14: VSSC | AF14: DDR1_DQ0 | AG14: DDR1_DQS0_N | AH14: VSSC | AI14: VSSC | AJ14: DDR1_DQ4 | AK14: N
B15: P | C15: RGMII0_TXD1 | D15: RGMII0_MDC | E15: RGMII1_IRQ | F15: RGMII1_MDIO | G15: UART2_TX | H15: UART4_CTS | I15: VSSC | J15: VDDIO33_SD1 | K15: VSSC | L15: VDDC | M15: VSSC | N15: VDDC | O15: VSSC | P15: VDDC | Q15: VSSC | R15: VDDC | S15: VSSC | T15: VDDC | U15: VSSC | V15: VDDC | W15: VSSC | X15: VDDC | Y15: VSSC | Z15: VDDC | AA15: VSSC | AB15: VSSC | AC15: VSSC | AD15: VSSC | AE15: VSSC | AF15: VSSC | AG15: VSSC | AH15: VSSC | AI15: DDR1_DM1 | AJ15: DDR1_DQ9 | AK15: P
B16: R | C16: RGMII0_TXD2 | D16: RGMII0_MDIO | E16: RGMII1_TXC | F16: RGMII1_MDC | G16: UART2_RX | H16: UART4_TX | I16: VSSC | J16: VDDIO18_1 | K16: VDDC | L16: VSSC | M16: VDDIO33_1 | N16: VSSC | O16: VDDC | P16: VSSC | Q16: VDDC | R16: VSSC | S16: VDDC | T16: VSSC | U16: VDDC | V16: VSSC | W16: VDDC | X16: VSSC | Y16: VDDC | Z16: VSSC | AA16: VDDC | AB16: VSSC | AC16: CSI_VDD18A | AD16: CSI_VDD18A | AE16: VSSC | AF16: DDR1_DQ2 | AG16: DDR1_DQS1_P | AH16: VSSC | AI16: VSSC | AJ16: DDR1_DQ11 | AK16: R
B17: T | C17: RGMII0_TXD3 | D17: RGMII0_IRQ | E17: RGMII1_RXCTRL | F17: RGMII1_RXC | G17: UART2_CTS | H17: UART2_RTS | I17: VSSC | J17: VDDIO18_1 | K17: VSSC | L17: VDDC | M17: VSSC | N17: VDDC | O17: VSSC | P17: VDDC | Q17: VSSC | R17: VDDC | S17: VSSC | T17: VDDC | U17: VSSC | V17: VDDC | W17: VSSC | X17: VDDC | Y17: VSSC | Z17: VDDC | AA17: VSSC | AB17: VSSC | AC17: VSSC | AD17: CSI_VDD18A | AE17: VSSC | AF17: DDR1_DQ10 | AG17: DDR1_DQS1_N | AH17: VSSC | AI17: DDR1_DQ13 | AJ17: DDR1_DQ15 | AK17: T
B18: U | C18: RGMII0_RXD0 | D18: RGMII0_REFCLKO | E18: RGMII1_RXD1 | F18: VSSC | G18: VSSC | H18: VSSC | I18: VSSC | J18: VDDIO33_RGMII | K18: VDDC | L18: VSSC | M18: VDDC | N18: VSSC | O18: VDDC | P18: VSSC | Q18: VDDC | R18: VSSC | S18: VDDC | T18: VSSC | U18: VDDC | V18: VSSC | W18: VDDC | X18: VSSC | Y18: VDDC | Z18: VSSC | AA18: VSSC | AB18: VSSC | AC18: VSSC | AD18: VSSC | AE18: VSSC | AF18: VSSC | AG18: VSSC | AH18: VSSC | AI18: DDR1_DQ14 | AJ18: DDR1_DQ8 | AK18: U
B19: V | C19: RGMII0_TXCTRL | D19: RGMII0_RXD3 | E19: RGMII1_RXD0 | F19: RGMII1_TXCTRL | G19: RGMII1_TXD3 | H19: UART4_RTS | I19: VSSC | J19: VDDIO33_RGMII | K19: VSSC | L19: VDDC | M19: VSSC | N19: VDDC | O19: VSSC | P19: VDDC | Q19: VSSC | R19: VDDC | S19: VSSC | T19: VDDC | U19: VSSC | V19: VDDC | W19: VSSC | X19: VDDC | Y19: VSSC | Z19: DDR_VDDQ | AA19: DDR_VDDQ | AB19: VSSC | AC19: DDR1_A11 | AD19: DDR1_A8 | AE19: VSSC | AF19: DDR1_A9 | AG19: DDR1_A13 | AH19: VSSC | AI19: VSSC | AJ19: DDR1_DQ12 | AK19: V
B20: W | C20: RGMII0_TXD0 | D20: VSSC | E20: VSSC | F20: VSSC | G20: RGMII1_TXD0 | H20: RGMII1_TXD2 | I20: VSSC | J20: VDDIO18_1 | K20: VDDC | L20: VSSC | M20: VDDC | N20: VSSC | O20: VDDC | P20: VSSC | Q20: VDDC | R20: VDDC_SENSE_N | S20: VDDC | T20: VSSC | U20: VDDC | V20: VSSC | W20: VDDC | X20: VSSC | Y20: VDDC | Z20: DDR_VDDQ | AA20: DDR_VDDQ | AB20: VSSC | AC20: DDR1_A7 | AD20: DDR1_A2 | AE20: VSSC | AF20: DDR1_A0 | AG20: DDR1_A5 | AH20: VSSC | AI20: DDR1_CLKP0 | AJ20: DDR1_A3 | AK20: W
B21: Y | D21: SSPERI_TXP[2] | E21: SSPERI_TXM[2] | F21: VSSC | G21: RGMII1_TXD1 | H21: VIVO0_D15 | I21: VSSC | J21: VDDIO18_1 | K21: VSSC | L21: VDDC | M21: VSSC | N21: VDDC | O21: VSSC | P21: VDDC | Q21: VSSC | R21: VDDC_SENSE_P | S21: VSSC | T21: VDDC | U21: VSSC | V21: VDDC | W21: VSSC | X21: VDDC | Y21: VSSC | Z21: DDR_VDDQ | AA21: DDR_VDDQ | AB21: DDR1_VDD18A_PLL | AC21: DDR1_A6 | AD21: DDR1_BA1 | AE21: VSSC | AF21: VSSC | AG21: VSSC | AH21: VSSC | AI21: DDR1_CLKN0 | AJ21: DDR1_A15 | AK21: Y
B22: AA | C22: SSPERI_TXP[3] | D22: SSPERI_TXM[3] | E22: VSSC | F22: VSSC | G22: VSSC | H22: VSSC | I22: VSSC | J22: VSSC | K22: VDDC | L22: VSSC | M22: VDDC | N22: VSSC | O22: VDDC | P22: VSSC | Q22: VDDC | R22: VSSC | S22: VDDC | T22: VSSC | U22: VDDC | V22: VSSC | W22: VDDC | X22: VSSC | Y22: VDDC | Z22: DDR_VDD11A | AA22: DDR_VDD11A | AB22: VSSC | AC22: VSSC | AD22: VSSC | AE22: VSSC | AF22: DDR1_RESETZ | AG22: DDR1_ZQ | AH22: VSSC | AI22: VSSC | AJ22: DDR1_A4 | AK22: AA
B23: AB | D23: SSPERI_RXM[3] | E23: SSPERI_RXP[3] | F23: VSSC | G23: VIVO0_D16 | H23: VIVO_CLK | I23: VSSC | J23: VDDIO33_0 | K23: VSSC | L23: VDDC | M23: VSSC | N23: VDDC | O23: VSSC | P23: VDDC | Q23: VSSC | R23: VDDC | S23: VSSC | T23: VDDC | U23: VSSC | V23: VDDC | W23: VSSC | X23: VDDC | Y23: VSSC | Z23: DDR_VDD11A | AA23: DDR_VDD11A | AB23: VSSC | AC23: DDR1_A16 | AD23: DDR1_A12 | AE23: VSSC | AF23: DDR1_BG0 | AG23: DDR1_CSB0 | AH23: VSSC | AI23: VSSC | AJ23: DDR1_BA0 | AK23: AB
B24: AC | C24: SSPERI_REF_CLK_M[1] | D24: SSPERI_REF_CLK_P[1] | E24: VSSC | F24: VSSC | G24: VIVO0_D10 | H24: VIVO0_D12 | I24: VSSC | J24: VDDIO33_0 | K24: VDDC | L24: VSSC | M24: VDDC | N24: VSSC | O24: VDDC | P24: VSSC | Q24: VDDC | R24: VSSC | S24: VDDC | T24: VSSC | U24: VDDC | V24: VSSC | W24: VDDC | X24: VSSC | Y24: VDDC | Z24: VSSC | AA24: VSSC | AB24: VSSC | AC24: DDR1_ODT0 | AD24: DDR1_ACT | AE24: VSSC | AF24: DDR1_CSB1 | AG24: DDR1_CKE0 | AH24: VSSC | AI24: DDR1_CLKN1 | AJ24: DDR1_A10 | AK24: AC
B25: AD | D25: SSPERI_RXM[2] | E25: SSPERI_RXP[2] | F25: VSSC | G25: VIVO0_D11 | H25: VIVO0_D13 | I25: VSSC | J25: PCIE1_VPH | K25: PCIE0_VPH | L25: VSSC | M25: VSSC | N25: VDDC | O25: VSSC | P25: VDDC | Q25: VSSC | R25: VDDC | S25: VSSC | T25: DDR_VDDQ | U25: DDR_VDDQ | V25: DDR_VDDQ | W25: DDR_VDD11A | X25: DDR_VDD11A | Y25: VSSC | Z25: DDR_VDDA | AA25: DDR_VDDA | AB25: VSSC | AC25: DDR1_A1 | AD25: DDR1_BG1 | AE25: VSSC | AF25: VSSC | AG25: VSSC | AH25: VSSC | AI25: DDR1_CLKP1 | AJ25: DDR1_A14 | AK25: AD
B26: AE | C26: SSPERI_REF_CLK_M[0] | D26: SSPERI_REF_CLK_P[0] | E26: VSSC | F26: VSSC | G26: VSSC | H26: VSSC | I26: VSSC | J26: PCIE1_VPH | K26: PCIE0_VPH | L26: VSSC | M26: HDMI_VPH | N26: VSSC | O26: DSI1_VDDA | P26: VSSC | Q26: VDDIO18_PLL | R26: VSSC_PLL | S26: VSSC | T26: DDR_VDDQ | U26: DDR_VDDQ | V26: DDR_VDDQ | W26: DDR_VDD11A | X26: DDR_VDD11A | Y26: VSSC | Z26: DDR_VDDA | AA26: DDR_VDDA | AB26: DDR_VDDA | AC26: VSSC | AD26: VSSC | AE26: VSSC | AF26: DDR1_DQ20 | AG26: DDR1_DQS2_N | AH26: VSSC | AI26: VSSC | AJ26: DDR1_DQ17 | AK26: AE
B27: AF | D27: SSPERI_RXM[1] | E27: SSPERI_RXP[1] | F27: VSSC | G27: VIVO0_D14 | H27: SSPERI_RESREF[1] | I27: VSSC | J27: VSSC | K27: VSSC | L27: VSSC | M27: VSSC | N27: HDMI_VP | O27: VSSC | P27: VSSC | Q27: VDDIO18_PLL | R27: VSSC_PLL | S27: VSSC | T27: VSSC | U27: VSSC | V27: VSSC | W27: VSSC | X27: DDR0_VDD18A_PLL | Y27: VSSC | Z27: VSSC | AA27: DDR_VDDA | AB27: VSSC | AC27: DDR_VDDQ | AD27: DDR_VDDQ | AE27: VSSC | AF27: DDR1_DQ29 | AG27: DDR1_DQS2_P | AH27: VSSC | AI27: DDR1_DQ16 | AJ27: DDR1_DM2 | AK27: AF
B28: AG | C28: SSPERI_TXM[0] | D28: SSPERI_TXP[0] | E28: VSSC | F28: VSSC | G28: PCIE0_L0_WAKEUP_X | H28: SSPERI_RESREF[0] | I28: VSSC | J28: PCIE_VP | K28: PCIE_VP | L28: PCIE_VP | M28: VSSC | N28: HDMI_VP | O28: DSI1_VDD18A | P28: VSSC | Q28: VDDIO18_0 | R28: VSSC | S28: VSSC | T28: DDR0_A1 | U28: DDR0_ODT0 | V28: DDR0_A16 | W28: VSSC | X28: DDR0_A6 | Y28: DDR0_A7 | Z28: DDR0_A11 | AA28: VSSC | AB28: DDR_VDDQ | AC28: DDR_VDDQ | AD28: DDR_VDDQ | AE28: VSSC | AF28: VSSC | AG28: VSSC | AH28: VSSC | AI28: DDR1_DQ19 | AJ28: DDR1_DQ21 | AK28: AG
B29: AH | D29: SSPERI_RXM[0] | E29: SSPERI_RXP[0] | F29: VSSC | G29: PCIE0_L0_CLKREQ_IN_X | H29: PCIE0_L0_RESET_X | I29: VSSC | J29: PCIE_VP | K29: PCIE_VP | L29: PCIE_VP | M29: VSSC | N29: VSSC | O29: DSI1_VDD18A | P29: VSSC | Q29: VDDIO18_0 | R29: VSSC | S29: VSSC | T29: DDR0_BG1 | U29: DDR0_ACT | V29: DDR0_A12 | W29: VSSC | X29: DDR0_BA1 | Y29: DDR0_A2 | Z29: DDR0_A8 | AA29: VSSC | AB29: DDR_VDDQ | AC29: DDR_VDDQ | AD29: DDR_VDDQ | AE29: VSSC | AF29: DDR1_DQ24 | AG29: DDR1_DQS3_N | AH29: VSSC | AI29: VSSC | AJ29: DDR1_DQ23 | AK29: AH
B30: AJ | C30: SSPERI_TXM[1] | D30: SSPERI_TXP[1] | E30: VSSC | F30: VSSC | G30: VSSC | H30: VSSC | I30: VSSC | J30: VSSC | K30: VSSC | L30: VSSC | M30: VSSC | N30: VSSC | O30: VSSC | P30: VSSC | Q30: VSSC | R30: VSSC | S30: VSSC | T30: VSSC | U30: VSSC | V30: VSSC | W30: VSSC | X30: VSSC | Y30: VSSC | Z30: VSSC | AA30: VSSC | AB30: VSSC | AC30: VSSC | AD30: VSSC | AE30: VSSC | AF30: DDR1_DQ28 | AG30: DDR1_DQS3_P | AH30: VSSC | AI30: DDR1_DQ18 | AJ30: DDR1_DQ22 | AK30: AJ
B31: AK | C31: VSSC | D31: VSSC | E31: PCIE1_L0_WAKEUP_X | F31: PCIE1_L0_CLKREQ_IN_X | G31: HDMI_HPD | H31: I2S0_SDI1 | I31: I2S0_SDI0 | J31: I2S0_MCLK | K31: VMON_N | L31: VSSC | M31: VSSC | N31: DDR0_DQ28 | O31: DDR0_DQ24 | P31: VSSC | Q31: DDR0_DQ29 | R31: DDR0_DQ20 | S31: VSSC | T31: DDR0_CSB1 | U31: DDR0_BG0 | V31: DDR0_RESETZ | W31: VSSC | X31: DDR0_A0 | Y31: DDR0_A9 | Z31: VSSC | AA31: DDR0_DQ10 | AB31: DDR0_DQ2 | AC31: VSSC | AD31: DDR0_DQ0 | AE31: DDR0_DQ3 | AF31: VSSC | AG31: VSSC | AH31: VSSC | AI31: VSSC | AJ31: DDR1_DM3 | AK31: AK
B32: AL | C32: HDMI_TMDSCLKN | D32: HDMI_TMDSCLKP | E32: VSSC | F32: PCIE1_L0_RESET_X | G32: HDMI_REXT | H32: I2S0_SDO | I32: I2S0_WSI | J32: I2S0_SCLK | K32: VMON_P | L32: VSSC | M32: VSSC | N32: DDR0_DQS3_P | O32: DDR0_DQS3_N | P32: VSSC | Q32: DDR0_DQS2_P | R32: DDR0_DQS2_N | S32: VSSC | T32: DDR0_CKE0 | U32: DDR0_CSB0 | V32: DDR0_ZQ | W32: VSSC | X32: DDR0_A5 | Y32: DDR0_A13 | Z32: VSSC | AA32: DDR0_DQS1_N | AB32: DDR0_DQS1_P | AC32: VSSC | AD32: DDR0_DQS0_N | AE32: DDR0_DQS0_P | AF32: VSSC | AG32: VSSC | AH32: VSSC | AI32: DDR1_DQ27 | AJ32: DDR1_DQ25 | AK32: AL
B33: AM | C33: HDMI_TMDSDATAN0 | D33: HDMI_TMDSDATAP0 | E33: VSSC | F33: VSSC | G33: VSSC | H33: VSSC | I33: VSSC | J33: VSSC | K33: VSSC | L33: VSSC | M33: VSSC | N33: VSSC | O33: VSSC | P33: VSSC | Q33: VSSC | R33: VSSC | S33: VSSC | T33: VSSC | U33: VSSC | V33: VSSC | W33: VSSC | X33: VSSC | Y33: VSSC | Z33: VSSC | AA33: VSSC | AB33: VSSC | AC33: VSSC | AD33: VSSC | AE33: VSSC | AF33: VSSC | AG33: VSSC | AH33: VSSC | AI33: DDR1_DQ30 | AJ33: DDR1_DQ31 | AK33: AM
B34: AN | C34: HDMI_TMDSDATAN1 | D34: HDMI_TMDSDATAP1 | E34: VSSC | F34: MIPI1_TX0P | G34: MIPI1_TX1P | H34: MIPI1_TX2P | I34: MIPI1_TX3P | J34: MIPI1_TX4P | K34: VSSC | L34: VSSC | M34: DDR0_DQ30 | N34: DDR0_DQ27 | O34: VSSC | P34: DDR0_DQ18 | Q34: VSSC | R34: DDR0_DQ16 | S34: DDR0_DQ19 | T34: VSSC | U34: DDR0_CLKP1 | V34: DDR0_CLKN1 | W34: VSSC | X34: VSSC | Y34: DDR0_CLKN0 | Z34: DDR0_CLKP0 | AA34: VSSC | AB34: DDR0_DQ14 | AC34: DDR0_DQ13 | AD34: VSSC | AE34: DDR0_DM1 | AF34: VSSC | AG34: DDR0_DQ7 | AH34: DDR0_DM0 | AI34: VSSC | AJ34: DDR1_DQ26 | AK34: AN
B35: AP | C35: VSSC | D35: HDMI_TMDSDATAN2 | E35: HDMI_TMDSDATAP2 | F35: MIPI1_TX0N | G35: MIPI1_TX1N | H35: MIPI1_TX2N | I35: MIPI1_TX3N | J35: MIPI1_TX4N | L35: DDR0_DQ26 | M35: DDR0_DQ31 | N35: DDR0_DQ25 | O35: DDR0_DM3 | P35: DDR0_DQ22 | Q35: DDR0_DQ23 | R35: DDR0_DQ21 | S35: DDR0_DM2 | T35: DDR0_DQ17 | U35: DDR0_A14 | V35: DDR0_A10 | W35: DDR0_BA0 | X35: DDR0_A4 | Y35: DDR0_A15 | Z35: DDR0_A3 | AA35: DDR0_DQ12 | AB35: DDR0_DQ8 | AC35: DDR0_DQ15 | AD35: DDR0_DQ11 | AE35: DDR0_DQ9 | AF35: DDR0_DQ4 | AG35: DDR0_DQ6 | AH35: DDR0_DQ1 | AI35: DDR0_DQ5 | AJ35: VSSC | AK35: AP
C36: 1 | D36: 2 | E36: 3 | F36: 4 | G36: 5 | H36: 6 | I36: 7 | J36: 8 | K36: 9 | L36: 10 | M36: 11 | N36: 12 | O36: 13 | P36: 14 | Q36: 15 | R36: 16 | S36: 17 | T36: 18 | U36: 19 | V36: 20 | W36: 21 | X36: 22 | Y36: 23 | Z36: 24 | AA36: 25 | AB36: 26 | AC36: 27 | AD36: 28 | AE36: 29 | AF36: 30 | AG36: 31 | AH36: 32 | AI36: 33 | AJ36: 34
I37: Pitch 0.65 mm
G39: BM1688 23mmX23mm FCBGA 1120 BAll Pinmap

Sheet 5.管脚默认状态
A1: Pin Number | B1: PIN Name | C1: Default Function | D1: Default Pull (PU/PD/NO PULL) | E1: IO TRAP (become input during reset) | F1: IO Type | G1: PowerDomain | H1: GROUP
A2: W1 | B2: RGMII0_TXD0 | C2: RGMII0_TXD0 | D2: NO PULL | F2: RGMII_IO | G2: VDDIO_RGMII0 | H2: G1
A3: P1 | B3: RGMII0_TXD1 | C3: RGMII0_TXD0 | D3: NO PULL | F3: RGMII_IO | G3: VDDIO_RGMII0 | H3: G1
A4: R1 | B4: RGMII0_TXD2 | C4: RGMII0_TXD2 | D4: NO PULL | F4: RGMII_IO | G4: VDDIO_RGMII0 | H4: G1
A5: T1 | B5: RGMII0_TXD3 | C5: RGMII0_TXD3 | D5: NO PULL | F5: RGMII_IO | G5: VDDIO_RGMII0 | H5: G1
A6: V1 | B6: RGMII0_TXCTRL | C6: RGMII0_TXCTRL | D6: NO PULL | F6: RGMII_IO | G6: VDDIO_RGMII0 | H6: G1
A7: U1 | B7: RGMII0_RXD0 | C7: RGMII0_RXD0 | D7: NO PULL | F7: RGMII_IO | G7: VDDIO_RGMII0 | H7: G1
A8: M1 | B8: RGMII0_RXD1 | C8: RGMII0_RXD1 | D8: NO PULL | F8: RGMII_IO | G8: VDDIO_RGMII0 | H8: G1
A9: N1 | B9: RGMII0_RXD2 | C9: RGMII0_RXD2 | D9: NO PULL | F9: RGMII_IO | G9: VDDIO_RGMII0 | H9: G1
A10: V2 | B10: RGMII0_RXD3 | C10: RGMII0_RXD3 | D10: NO PULL | F10: RGMII_IO | G10: VDDIO_RGMII0 | H10: G1
A11: L2 | B11: RGMII0_RXCTRL | C11: RGMII0_RXCTRL | D11: NO PULL | F11: RGMII_IO | G11: VDDIO_RGMII0 | H11: G1
A12: M2 | B12: RGMII0_TXC | C12: RGMII0_TXC | D12: NO PULL | F12: RGMII_IO | G12: VDDIO_RGMII0 | H12: G1
A13: N2 | B13: RGMII0_RXC | C13: RGMII0_RXC | D13: NO PULL | F13: RGMII_IO | G13: VDDIO_RGMII0 | H13: G1
... A70: B3 | B70: SPK_EN | C70: GPIO6 | D70: PD | F70: 1.8V_IO | G70: VDDIO18 | H70: G9
A71: A2 | B71: AUX0 | C71: AUX0 | D71: PD | E71: V | F71: 1.8V_IO | G71: VDDIO18 | H71: G9
A72: E8 | B72: PWM0 | C72: PWM0 | D72: NO PULL | F72: 1.8V_IO | G72: VDDIO18 | H72: G9
A73: E9 | B73: PWM1 | C73: PWM1 | D73: NO PULL | F73: 1.8V_IO | G73: VDDIO18 | H73: G9
A74: D8 | B74: PWM2 | C74: PWM2 | D74: NO PULL | F74: 1.8V_IO | G74: VDDIO18 | H74: G9
A75: E10 | B75: PWM3 | C75: PWM3 | D75: NO PULL | F75: 1.8V_IO | G75: VDDIO18 | H75: G9
A76: D17 | B76: SD0_CD_X | C76: SD0_CD_X | D76: PU | F76: 1.8V_IO | G76: VDDIO18 | H76: G9
A77: D19 | B77: SD0_PWR_EN | C77: SD0_PWR_EN | D77: PD | E77: V | F77: 1.8V_IO | G77: VDDIO18 | H77: G9
A78: D9 | B78: FAN0 | C78: PWM4 | D78: PU | F78: 1.8V_IO | G78: VDDIO18 | H78: G9
A79: D10 | B79: FAN1 | C79: PWM5 | D79: PU | F79: 1.8V_IO | G79: VDDIO18 | H79: G9
A80: E14 | B80: SPI0_CS_X | C80: SPI0_CS_X | D80: PD | E80: V | F80: 1.8V_IO | G80: VDDIO18 | H80: G9
A81: E13 | B81: SPI0_SDI | C81: SPI0_SDI | D81: PD | E81: V | F81: 1.8V_IO | G81: VDDIO18 | H81: G9
A82: F12 | B82: SPI0_SDO | C82: SPI0_SDO | D82: PD | E82: V | F82: 1.8V_IO | G82: VDDIO18 | H82: G9
A83: E12 | B83: SPI0_SCK | C83: SPI0_SCK | D83: PD | E83: V | F83: 1.8V_IO | G83: VDDIO18 | H83: G9
A84: H3 | B84: UART0_TX | C84: UART0_TX | D84: PU | F84: 18OD33(3.3V) | G84: VDDIO33 | H84: G11
A85: H4 | B85: UART0_RX | C85: UART0_RX | D85: PU | F85: 18OD33(3.3V) | G85: VDDIO33 | H85: G11
A86: G4 | B86: UART1_TX | C86: UART1_TX | D86: PU | E86: V | F86: 18OD33(3.3V) | G86: VDDIO33 | H86: G11
A87: G3 | B87: UART1_RTS | C87: UART1_RTS | D87: PD | F87: 18OD33(3.3V) | G87: VDDIO33 | H87: G11
A88: F3 | B88: UART1_RX | C88: UART1_RX | D88: PU | F88: 18OD33(3.3V) | G88: VDDIO33 | H88: G11
A89: F4 | B89: UART1_CTS | C89: UART1_CTS | D89: PD | F89: 18OD33(3.3V) | G89: VDDIO33 | H89: G11
A90: G5 | B90: EMMC_RST_X | C90: EMMC_RST_X | D90: PD | F90: 18OD33(1.8V) | G90: VDDIO18_EMMC | H90: G11
A91: F5 | B91: EMMC_CLK | C91: EMMC_CLK | D91: PD | F91: 18OD33(1.8V) | G91: VDDIO18_EMMC | H91: G11
A92: E3 | B92: EMMC_CMD | C92: EMMC_CMD | D92: PD | E92: V | F92: 18OD33(1.8V) | G92: VDDIO18_EMMC | H92: G11
A93: G6 | B93: EMMC_D0 | C93: EMMC_D0 | D93: PU | E93: V | F93: 18OD33(1.8V) | G93: VDDIO18_EMMC | H93: G11
A94: H6 | B94: EMMC_D1 | C94: EMMC_D1 | D94: PD | F94: 18OD33(1.8V) | G94: VDDIO18_EMMC | H94: G11
A95: F6 | B95: EMMC_D2 | C95: EMMC_D2 | D95: PD | F95: 18OD33(1.8V) | G95: VDDIO18_EMMC | H95: G11
A96: F7 | B96: EMMC_D3 | C96: EMMC_D3 | D96: PU | E96: V | F96: 18OD33(1.8V) | G96: VDDIO18_EMMC | H96: G11
...

Sheet 6.MIPI_PAD切GPIO说明
A1: MIPI 如何设成 GPIO
A2: 注： 1、MIPI PAD上电到uboot阶段会有1.1V中间电平现象，故不建议使用做GPO功能。若确定需使用做GPO功能，需注意评估此中间电平影响； 2、MIPIPAD非Fail-safe引脚，注意上电时序，避免电压倒灌引起开机异常；
A3: MIPI TX
A4: PAD_MIPI0_TX0P | B4: 0x28104E90 bit[3] 1=GPIO;0=MIPI (default)
A5: PAD_MIPI0_TX0N | B5: 0x28104E94 bit[3] 1=GPIO;0=MIPI (default)
A6: ……
A7: PAD_MIPI0_TX4P | B7: 0x28104EB0 bit[3] 1=GPIO;0=MIPI (default)
A8: PAD_MIPI0_TX4N | B8: 0x28104EB4 bit[3] 1=GPIO;0=MIPI (default)
A10: PAD_MIPI1_TX0P | B10: 0x28104EB8 bit[3] 1=GPIO;0=MIPI (default)
A11: PAD_MIPI1_TX0N | B11: 0x28104EBC bit[3] 1=GPIO;0=MIPI (default)
A12: ……
A13: PAD_MIPI1_TX4P | B13: 0x28104ED8 bit[3] 1=GPIO;0=MIPI (default)
A14: PAD_MIPI1_TX4N | B14: 0x28104EDC bit[3] 1=GPIO;0=MIPI (default)
A16: MIPI RX
A17: PAD_MIPI_RX0P | B17: 0x28104E00 bit[3] 1=GPIO;0=MIPI (default)
A18: PAD_MIPI_RX0N | B18: 0x28104E04 bit[3] 1=GPIO;0=MIPI (default)
A19: PAD_MIPI_RX1P | B19: 0x28104E08 bit[3] 1=GPIO;0=MIPI (default)
A20: PAD_MIPI_RX1N | B20: 0x28104E0C bit[3] 1=GPIO;0=MIPI (default)
A21: ……
A22: PAD_MIPI_RX17P | B22: 0x28104E88 bit[3] 1=GPIO;0=MIPI (default)
A23: PAD_MIPI_RX17N | B23: 0x28104E8C bit[3] 1=GPIO;0=MIPI (default)
